
      INFO   Will watch for changes in these directories: ['/Users/N133723/Desktop/tlabchaat-355-24/cost-estimator-calc-service']
      INFO   Uvicorn running on http://0.0.0.0:8000 (Press CTRL+C to quit)
      INFO   Started reloader process [38141] using WatchFiles
2025-07-31 15:16:55,883 | INFO | cost_estimator_calc_service | Async SpannerClient initialized for database: projects/anbc-hcb-dev/instances/provider-de/databases/cost-estimator-secure
2025-07-31 15:16:55,883 | INFO | cost_estimator_calc_service | Connection pool size: 10, Max workers: 20
      INFO   Started server process [38144]
      INFO   Waiting for application startup.
2025-07-31 15:16:55,884 | INFO | cost_estimator_calc_service | Executing async query: SELECT payment_method_cd, score FROM payment_method_hierarchy
2025-07-31 15:16:55,884 | INFO | cost_estimator_calc_service | Query params: None
/Users/N133723/Library/Python/3.12/lib/python/site-packages/google/auth/_default.py:76: UserWarning: Your application has authenticated using end user credentials from Google Cloud SDK without a quota project. You might receive a "quota exceeded" or "API not enabled" error. See the following page for troubleshooting: https://cloud.google.com/docs/authentication/adc-troubleshooting/user-creds. 
  warnings.warn(_CLOUD_SDK_CREDENTIALS_WARNING)
2025-07-31 15:17:22,532 | ERROR | cost_estimator_calc_service | Error executing async read-only query: Timeout of 30.0s exceeded, last exception: 503 Getting metadata from plugin failed with error: Reauthentication is needed. Please run `gcloud auth application-default login` to reauthenticate.
2025-07-31 15:17:22,533 | ERROR | cost_estimator_calc_service | Query: SELECT payment_method_cd, score FROM payment_method_hierarchy
2025-07-31 15:17:22,533 | ERROR | cost_estimator_calc_service | Params: None
2025-07-31 15:17:22,533 | ERROR | cost_estimator_calc_service | Exception type: <class 'google.api_core.exceptions.RetryError'>
2025-07-31 15:17:22,533 | ERROR | cost_estimator_calc_service | Exception details: Timeout of 30.0s exceeded, last exception: 503 Getting metadata from plugin failed with error: Reauthentication is needed. Please run `gcloud auth application-default login` to reauthenticate.
2025-07-31 15:17:22,533 | INFO | cost_estimator_calc_service | Cached payment_method_hierarchy with 0 entries.
      INFO   Application startup complete.
2025-07-31 15:17:27,941 | INFO | cost_estimator_calc_service | Async SpannerClient initialized for database: projects/anbc-hcb-dev/instances/provider-de/databases/cost-estimator-secure
2025-07-31 15:17:27,942 | INFO | cost_estimator_calc_service | Connection pool size: 10, Max workers: 20
benefit_request benefitProductType='Medical' membershipID='5~265642286+34+44+20250101+784461+AM+39' planIdentifier='3~' serviceInfo=[ServiceInfo(serviceCodeInfo=ServiceCodeInfo(providerType=[ProviderType(code='IO')], placeOfService=[PlaceOfService(code='22')], providerSpecialty=[ProviderSpecialty(code='12345')], code='28054', type='CPT4'))]
CostEstimatorRateCriteria fields: {'providerIdentificationNumber': <class 'str'>, 'serviceCode': <class 'str'>, 'serviceType': <class 'str'>, 'serviceLocationNumber': typing.Optional[str], 'networkId': typing.Optional[str], 'placeOfService': <class 'str'>, 'zipCode': <class 'str'>, 'isOutofNetwork': <class 'bool'>, 'providerSpecialtyCode': typing.Optional[str], 'providerType': typing.Optional[str]}
rate_criteria CostEstimatorRateCriteria(providerIdentificationNumber='7614094', serviceCode='28054', serviceType='CPT4', serviceLocationNumber='426176', networkId='12808', placeOfService='22', zipCode='07083', isOutofNetwork=False, providerSpecialtyCode='12345', providerType='IO')
2025-07-31 15:17:27,944 | INFO | cost_estimator_calc_service | Executing async query: SELECT MAX(RATE) AS RATE
FROM CET_CLAIM_BASED_AMOUNTS
WHERE
    PROVIDER_IDENTIFICATION_NBR = @provideridentificationnumber
    AND NETWORK_ID = @networkid
    AND PLACE_OF_SERVICE_CD = @placeofservice
    AND SERVICE_CD = @servicecd
    AND SERVICE_TYPE_CD = @servicetype
2025-07-31 15:17:27,944 | INFO | cost_estimator_calc_service | Query params: {'servicecd': '28054', 'provideridentificationnumber': '7614094', 'placeofservice': '22', 'servicetype': 'CPT4', 'networkid': '12808', 'servicelocationnumber': '426176'}
/Users/N133723/Library/Python/3.12/lib/python/site-packages/google/auth/_default.py:76: UserWarning: Your application has authenticated using end user credentials from Google Cloud SDK without a quota project. You might receive a "quota exceeded" or "API not enabled" error. See the following page for troubleshooting: https://cloud.google.com/docs/authentication/adc-troubleshooting/user-creds. 
  warnings.warn(_CLOUD_SDK_CREDENTIALS_WARNING)
WARNING: All log messages before absl::InitializeLog() is called are written to STDERR
I0000 00:00:1753993047.945828 3845962 fork_posix.cc:71] Other threads are currently calling into gRPC, skipping fork() handlers
2025-07-31 15:17:29,241 | INFO | cost_estimator_calc_service | Successfully retrieved new token
2025-07-31 15:17:29,587 | INFO | cost_estimator_calc_service | Successfully retrieved new token
2025-07-31 15:17:54,926 | ERROR | cost_estimator_calc_service | Error executing async read-only query: Timeout of 30.0s exceeded, last exception: 503 Getting metadata from plugin failed with error: Reauthentication is needed. Please run `gcloud auth application-default login` to reauthenticate.
2025-07-31 15:17:54,926 | ERROR | cost_estimator_calc_service | Query: SELECT MAX(RATE) AS RATE
FROM CET_CLAIM_BASED_AMOUNTS
WHERE
    PROVIDER_IDENTIFICATION_NBR = @provideridentificationnumber
    AND NETWORK_ID = @networkid
    AND PLACE_OF_SERVICE_CD = @placeofservice
    AND SERVICE_CD = @servicecd
    AND SERVICE_TYPE_CD = @servicetype
2025-07-31 15:17:54,926 | ERROR | cost_estimator_calc_service | Params: {'servicecd': '28054', 'provideridentificationnumber': '7614094', 'placeofservice': '22', 'servicetype': 'CPT4', 'networkid': '12808', 'servicelocationnumber': '426176'}
2025-07-31 15:17:54,926 | ERROR | cost_estimator_calc_service | Exception type: <class 'google.api_core.exceptions.RetryError'>
2025-07-31 15:17:54,926 | ERROR | cost_estimator_calc_service | Exception details: Timeout of 30.0s exceeded, last exception: 503 Getting metadata from plugin failed with error: Reauthentication is needed. Please run `gcloud auth application-default login` to reauthenticate.
2025-07-31 15:17:54,926 | INFO | cost_estimator_calc_service | Claim-based rate result: []
2025-07-31 15:17:54,926 | WARNING | cost_estimator_calc_service | Empty or malformed result
2025-07-31 15:17:54,926 | INFO | cost_estimator_calc_service | No claim-based rate found, proceeding to get provider info
2025-07-31 15:17:54,926 | INFO | cost_estimator_calc_service | Executing async query: SELECT DISTINCT PROVIDER_BUSINESS_GROUP_NBR, PRODUCT_CD, RATING_SYSTEM_CD, EPDB_GEOGRAPHIC_AREA_CD
FROM CET_PROVIDERS
WHERE
    PROVIDER_IDENTIFICATION_NBR = @provideridentificationnumber
    AND NETWORK_ID = @networkid
    AND SERVICE_LOCATION_NBR = @servicelocationnumber
2025-07-31 15:17:54,926 | INFO | cost_estimator_calc_service | Query params: {'servicecd': '28054', 'provideridentificationnumber': '7614094', 'placeofservice': '22', 'servicetype': 'CPT4', 'networkid': '12808', 'servicelocationnumber': '426176'}
/Users/N133723/Library/Python/3.12/lib/python/site-packages/google/auth/_default.py:76: UserWarning: Your application has authenticated using end user credentials from Google Cloud SDK without a quota project. You might receive a "quota exceeded" or "API not enabled" error. See the following page for troubleshooting: https://cloud.google.com/docs/authentication/adc-troubleshooting/user-creds. 
  warnings.warn(_CLOUD_SDK_CREDENTIALS_WARNING)
I0000 00:00:1753993077.931176 3845962 fork_posix.cc:71] Other threads are currently calling into gRPC, skipping fork() handlers
2025-07-31 15:18:26,159 | ERROR | cost_estimator_calc_service | Error executing async read-only query: Timeout of 30.0s exceeded, last exception: 503 Getting metadata from plugin failed with error: Reauthentication is needed. Please run `gcloud auth application-default login` to reauthenticate.
2025-07-31 15:18:26,159 | ERROR | cost_estimator_calc_service | Query: SELECT DISTINCT PROVIDER_BUSINESS_GROUP_NBR, PRODUCT_CD, RATING_SYSTEM_CD, EPDB_GEOGRAPHIC_AREA_CD
FROM CET_PROVIDERS
WHERE
    PROVIDER_IDENTIFICATION_NBR = @provideridentificationnumber
    AND NETWORK_ID = @networkid
    AND SERVICE_LOCATION_NBR = @servicelocationnumber
2025-07-31 15:18:26,159 | ERROR | cost_estimator_calc_service | Params: {'servicecd': '28054', 'provideridentificationnumber': '7614094', 'placeofservice': '22', 'servicetype': 'CPT4', 'networkid': '12808', 'servicelocationnumber': '426176'}
2025-07-31 15:18:26,159 | ERROR | cost_estimator_calc_service | Exception type: <class 'google.api_core.exceptions.RetryError'>
2025-07-31 15:18:26,159 | ERROR | cost_estimator_calc_service | Exception details: Timeout of 30.0s exceeded, last exception: 503 Getting metadata from plugin failed with error: Reauthentication is needed. Please run `gcloud auth application-default login` to reauthenticate.
2025-07-31 15:18:26,159 | INFO | cost_estimator_calc_service | Provider info result: []
2025-07-31 15:18:26,159 | INFO | cost_estimator_calc_service | No provider info results found
2025-07-31 15:18:26,159 | ERROR | cost_estimator_calc_service | Error in get_rate: float() argument must be a string or a real number, not 'NoneType'
      INFO   127.0.0.1:58527 - "POST /costestimator/v1/rate HTTP/1.1" 200
