INFO:     127.0.0.1:56732 - "POST /costestimator/v1/rate HTTP/1.1" 500 Internal Server Error
ERROR:    Exception in ASGI application
Traceback (most recent call last):
  File "/Users/N133723/Library/Python/3.12/lib/python/site-packages/uvicorn/protocols/http/httptools_impl.py", line 409, in run_asgi
    result = await app(  # type: ignore[func-returns-value]
             ^^^^^^^^^^^^^^^^^^^^^^^^^^^^^^^^^^^^^^^^^^^^^^
  File "/Users/N133723/Library/Python/3.12/lib/python/site-packages/uvicorn/middleware/proxy_headers.py", line 60, in __call__
    return await self.app(scope, receive, send)
           ^^^^^^^^^^^^^^^^^^^^^^^^^^^^^^^^^^^^
  File "/Users/N133723/Library/Python/3.12/lib/python/site-packages/fastapi/applications.py", line 1054, in __call__
    await super().__call__(scope, receive, send)
  File "/Users/N133723/Library/Python/3.12/lib/python/site-packages/starlette/applications.py", line 112, in __call__
    await self.middleware_stack(scope, receive, send)
  File "/Users/N133723/Library/Python/3.12/lib/python/site-packages/starlette/middleware/errors.py", line 187, in __call__
    raise exc
  File "/Users/N133723/Library/Python/3.12/lib/python/site-packages/starlette/middleware/errors.py", line 165, in __call__
    await self.app(scope, receive, _send)
  File "/Users/N133723/Library/Python/3.12/lib/python/site-packages/starlette/middleware/exceptions.py", line 62, in __call__
    await wrap_app_handling_exceptions(self.app, conn)(scope, receive, send)
  File "/Users/N133723/Library/Python/3.12/lib/python/site-packages/starlette/_exception_handler.py", line 53, in wrapped_app
    raise exc
  File "/Users/N133723/Library/Python/3.12/lib/python/site-packages/starlette/_exception_handler.py", line 42, in wrapped_app
    await app(scope, receive, sender)
  File "/Users/N133723/Library/Python/3.12/lib/python/site-packages/starlette/routing.py", line 714, in __call__
    await self.middleware_stack(scope, receive, send)
  File "/Users/N133723/Library/Python/3.12/lib/python/site-packages/starlette/routing.py", line 734, in app
    await route.handle(scope, receive, send)
  File "/Users/N133723/Library/Python/3.12/lib/python/site-packages/starlette/routing.py", line 288, in handle
    await self.app(scope, receive, send)
  File "/Users/N133723/Library/Python/3.12/lib/python/site-packages/starlette/routing.py", line 76, in app
    await wrap_app_handling_exceptions(app, request)(scope, receive, send)
  File "/Users/N133723/Library/Python/3.12/lib/python/site-packages/starlette/_exception_handler.py", line 53, in wrapped_app
    raise exc
  File "/Users/N133723/Library/Python/3.12/lib/python/site-packages/starlette/_exception_handler.py", line 42, in wrapped_app
    await app(scope, receive, sender)
  File "/Users/N133723/Library/Python/3.12/lib/python/site-packages/starlette/routing.py", line 73, in app
    response = await f(request)
               ^^^^^^^^^^^^^^^^
  File "/Users/N133723/Library/Python/3.12/lib/python/site-packages/fastapi/routing.py", line 301, in app
    raw_response = await run_endpoint_function(
                   ^^^^^^^^^^^^^^^^^^^^^^^^^^^^
  File "/Users/N133723/Library/Python/3.12/lib/python/site-packages/fastapi/routing.py", line 212, in run_endpoint_function
    return await dependant.call(**values)
           ^^^^^^^^^^^^^^^^^^^^^^^^^^^^^^
  File "/Users/N133723/Desktop/july 11/cost-estimator-calc-service/app/api/v1/routes/requests.py", line 19, in estimate_cost
    rate = await service.estimate_cost(request)
           ^^^^^^^^^^^^^^^^^^^^^^^^^^^^^^^^^^^^
  File "/Users/N133723/Desktop/july 11/cost-estimator-calc-service/app/services/impl/cost_estimation_service_impl.py", line 26, in estimate_cost
    benefit_request = CostEstimatorMapper.to_benefit_request(request)
                      ^^^^^^^^^^^^^^^^^^^^^^^^^^^^^^^^^^^^^^^^^^^^^^^
  File "/Users/N133723/Desktop/july 11/cost-estimator-calc-service/app/mappers/cost_estimator_mapper.py", line 31, in to_benefit_request
    return BenefitRequest(
           ^^^^^^^^^^^^^^^
  File "/Users/N133723/Library/Python/3.12/lib/python/site-packages/pydantic/main.py", line 253, in __init__
    validated_self = self.__pydantic_validator__.validate_python(data, self_instance=self)
                     ^^^^^^^^^^^^^^^^^^^^^^^^^^^^^^^^^^^^^^^^^^^^^^^^^^^^^^^^^^^^^^^^^^^^^
pydantic_core._pydantic_core.ValidationError: 1 validation error for BenefitRequest
serviceInfo.0.serviceCodeInfo.providerSpecialty
  Field required [type=missing, input_value={'code': '99214', 'type':...vice': [{'code': '11'}]}, input_type=dict]
    For further information visit https://errors.pydantic.dev/2.11/v/missing
