  async def test_real_service_integration():
        """Test service integration with real external services."""
        # Skip if real services are not configured
        if not os.getenv("ENABLE_REAL_INTEGRATION_TESTS"):
            pytest.skip("Real integration tests not enabled. Set ENABLE_REAL_INTEGRATION_TESTS=1 to run.")
    
        from app.services.impl.cost_estimation_service_impl import CostEstimationServiceImpl
        from app.schemas.cost_estimator_request import CostEstimatorRequest
    
        # Create real request object
        request_data = {
            "membershipId": "5~186103331+10+7+20240101+793854+8A+829",
            "zipCode": "85305",
            "benefitProductType": "Medical",
            "languageCode": "11",
            "service": {
                "code": "99214",
                "type": "CPT4",
                "description": "Adult Office visit Age 30-39",
                "placeOfService": {"code": "11"}
            },
            "providerInfo": [
                {
                    "serviceLocation": "000761071",
                    "providerType": "HO",
                    "speciality": {"code": "91017"},
                    "taxIdentificationNumber": "0000431173518",
                    "taxIdQualifier": "SN",
                    "providerNetworks": {"networkID": "58921"},
                    "providerIdentificationNumber": "0004000317",
                    "nationalProviderId": {"nationalProviderId": "1386660504"},
                    "providerNetworkParticipation": {"providerTier": "1"}
                }
            ]
        }
    
>       request = CostEstimatorRequest(**request_data)
                  ^^^^^^^^^^^^^^^^^^^^^^^^^^^^^^^^^^^^
E       pydantic_core._pydantic_core.ValidationError: 4 validation errors for CostEstimatorRequest
E       service.supportingService
E         Field required [type=missing, input_value={'code': '99214', 'type':...ervice': {'code': '11'}}, input_type=dict]
E           For further information visit https://errors.pydantic.dev/2.11/v/missing
E       service.modifier
E         Field required [type=missing, input_value={'code': '99214', 'type':...ervice': {'code': '11'}}, input_type=dict]
E           For further information visit https://errors.pydantic.dev/2.11/v/missing
E       service.diagnosisCode
E         Field required [type=missing, input_value={'code': '99214', 'type':...ervice': {'code': '11'}}, input_type=dict]
E           For further information visit https://errors.pydantic.dev/2.11/v/missing
E       providerInfo.0.nationalProviderId
E         Input should be a valid string [type=string_type, input_value={'nationalProviderId': '1386660504'}, input_type=dict]
E           For further information visit https://errors.pydantic.dev/2.11/v/string_type

tests/test_integration_real.py:106: ValidationError
___________________________________________________________________________________ test_real_accumulator_service ____________________________________________________________________________________

    @pytest.mark.integration
    @pytest.mark.real_services
    def test_real_accumulator_service():
        """Test real accumulator service integration."""
        if not os.getenv("ENABLE_REAL_INTEGRATION_TESTS"):
            pytest.skip("Real integration tests not enabled. Set ENABLE_REAL_INTEGRATION_TESTS=1 to run.")
    
        from app.services.impl.accumulator_service_impl import AccumulatorServiceImpl
        from app.schemas.cost_estimator_request import CostEstimatorRequest
    
        async def test_accumulator_service():
            service = AccumulatorServiceImpl()
    
            # Create a real request
            request_data = {
                "membershipId": "5~186103331+10+7+20240101+793854+8A+829",
                "zipCode": "85305",
                "benefitProductType": "Medical",
                "languageCode": "11",
                "service": {
                    "code": "99214",
                    "type": "CPT4",
                    "description": "Adult Office visit Age 30-39",
                    "placeOfService": {"code": "11"}
                },
                "providerInfo": [
                    {
                        "serviceLocation": "000761071",
                        "providerType": "HO",
                        "specialty": {"code": "91017"},
                        "taxIdentificationNumber": "0000431173518",
                        "taxIdQualifier": "SN",
                        "providerNetworks": {"networkID": "58921"},
                        "providerIdentificationNumber": "0004000317",
                        "nationalProviderId": "1386660504",
                        "providerNetworkParticipation": {"providerTier": "1"}
                    }
                ]
            }
    
            request = CostEstimatorRequest(**request_data)
    
            try:
                result = await service.get_accumulator(request)
                assert result is not None
            except Exception as e:
                # Service might be unavailable, which is acceptable for integration tests
                assert "error" in str(e).lower() or "unavailable" in str(e).lower()
    
>       asyncio.run(test_accumulator_service())

tests/test_integration_real.py:203: 
_ _ _ _ _ _ _ _ _ _ _ _ _ _ _ _ _ _ _ _ _ _ _ _ _ _ _ _ _ _ _ _ _ _ _ _ _ _ _ _ _ _ _ _ _ _ _ _ _ _ _ _ _ _ _ _ _ _ _ _ _ _ _ _ _ _ _ _ _ _ _ _ _ _ _ _ _ _ _ _ _ _ _ _ _ _ _ _ _ _ _ _ _ _ _ _ _ _ _ 
/Library/Frameworks/Python.framework/Versions/3.12/lib/python3.12/asyncio/runners.py:194: in run
    return runner.run(main)
           ^^^^^^^^^^^^^^^^
/Library/Frameworks/Python.framework/Versions/3.12/lib/python3.12/asyncio/runners.py:118: in run
    return self._loop.run_until_complete(task)
           ^^^^^^^^^^^^^^^^^^^^^^^^^^^^^^^^^^^
/Library/Frameworks/Python.framework/Versions/3.12/lib/python3.12/asyncio/base_events.py:687: in run_until_complete
    return future.result()
           ^^^^^^^^^^^^^^^
_ _ _ _ _ _ _ _ _ _ _ _ _ _ _ _ _ _ _ _ _ _ _ _ _ _ _ _ _ _ _ _ _ _ _ _ _ _ _ _ _ _ _ _ _ _ _ _ _ _ _ _ _ _ _ _ _ _ _ _ _ _ _ _ _ _ _ _ _ _ _ _ _ _ _ _ _ _ _ _ _ _ _ _ _ _ _ _ _ _ _ _ _ _ _ _ _ _ _ 

    async def test_accumulator_service():
        service = AccumulatorServiceImpl()
    
        # Create a real request
        request_data = {
            "membershipId": "5~186103331+10+7+20240101+793854+8A+829",
            "zipCode": "85305",
            "benefitProductType": "Medical",
            "languageCode": "11",
            "service": {
                "code": "99214",
                "type": "CPT4",
                "description": "Adult Office visit Age 30-39",
                "placeOfService": {"code": "11"}
            },
            "providerInfo": [
                {
                    "serviceLocation": "000761071",
                    "providerType": "HO",
                    "specialty": {"code": "91017"},
                    "taxIdentificationNumber": "0000431173518",
                    "taxIdQualifier": "SN",
                    "providerNetworks": {"networkID": "58921"},
                    "providerIdentificationNumber": "0004000317",
                    "nationalProviderId": "1386660504",
                    "providerNetworkParticipation": {"providerTier": "1"}
                }
            ]
        }
    
>       request = CostEstimatorRequest(**request_data)
                  ^^^^^^^^^^^^^^^^^^^^^^^^^^^^^^^^^^^^
E       pydantic_core._pydantic_core.ValidationError: 4 validation errors for CostEstimatorRequest
E       service.supportingService
E         Field required [type=missing, input_value={'code': '99214', 'type':...ervice': {'code': '11'}}, input_type=dict]
E           For further information visit https://errors.pydantic.dev/2.11/v/missing
E       service.modifier
E         Field required [type=missing, input_value={'code': '99214', 'type':...ervice': {'code': '11'}}, input_type=dict]
E           For further information visit https://errors.pydantic.dev/2.11/v/missing
E       service.diagnosisCode
E         Field required [type=missing, input_value={'code': '99214', 'type':...ervice': {'code': '11'}}, input_type=dict]
E           For further information visit https://errors.pydantic.dev/2.11/v/missing
E       providerInfo.0.speciality
E         Field required [type=missing, input_value={'serviceLocation': '0007...: {'providerTier': '1'}}, input_type=dict]
E           For further information visit https://errors.pydantic.dev/2.11/v/missing

tests/test_integration_real.py:194: ValidationError
___________________________________________________________________________________ test_real_database_integration ___________________________________________________________________________________

    async def test_database():
        repository = CostEstimatorRepositoryImpl()
    
        # Create real rate criteria
        rate_criteria = CostEstimatorRateCriteria(
            serviceCode="99214",
            providerIdentificationNumber="0004000317",
            placeOfService="11",
            serviceType="CPT4",
            networkId="58921",
            serviceLocationNumber="000761071",
            zipCode="85305",
            isOutofNetwork=False,
            providerSpecialtyCode="91017",
            providerType="HO"
        )
    
        try:
            result = await repository.get_rate(rate_criteria=rate_criteria)
            assert result is not None
>           assert isinstance(result, (int, float))
E           AssertionError: assert False
E            +  where False = isinstance('NA', (<class 'int'>, <class 'float'>))

tests/test_integration_real.py:236: AssertionError

During handling of the above exception, another exception occurred:

    @pytest.mark.integration
    @pytest.mark.real_services
    def test_real_database_integration():
        """Test real database integration."""
        if not os.getenv("ENABLE_REAL_INTEGRATION_TESTS"):
            pytest.skip("Real integration tests not enabled. Set ENABLE_REAL_INTEGRATION_TESTS=1 to run.")
    
        from app.repository.impl.cost_estimator_repository_impl import CostEstimatorRepositoryImpl
        from app.models.rate_criteria import CostEstimatorRateCriteria
    
        async def test_database():
            repository = CostEstimatorRepositoryImpl()
    
            # Create real rate criteria
            rate_criteria = CostEstimatorRateCriteria(
                serviceCode="99214",
                providerIdentificationNumber="0004000317",
                placeOfService="11",
                serviceType="CPT4",
                networkId="58921",
                serviceLocationNumber="000761071",
                zipCode="85305",
                isOutofNetwork=False,
                providerSpecialtyCode="91017",
                providerType="HO"
            )
    
            try:
                result = await repository.get_rate(rate_criteria=rate_criteria)
                assert result is not None
                assert isinstance(result, (int, float))
            except Exception as e:
                # Database might be unavailable, which is acceptable for integration tests
                assert "error" in str(e).lower() or "unavailable" in str(e).lower()
    
>       asyncio.run(test_database())

tests/test_integration_real.py:241: 
_ _ _ _ _ _ _ _ _ _ _ _ _ _ _ _ _ _ _ _ _ _ _ _ _ _ _ _ _ _ _ _ _ _ _ _ _ _ _ _ _ _ _ _ _ _ _ _ _ _ _ _ _ _ _ _ _ _ _ _ _ _ _ _ _ _ _ _ _ _ _ _ _ _ _ _ _ _ _ _ _ _ _ _ _ _ _ _ _ _ _ _ _ _ _ _ _ _ _ 
/Library/Frameworks/Python.framework/Versions/3.12/lib/python3.12/asyncio/runners.py:194: in run
    return runner.run(main)
           ^^^^^^^^^^^^^^^^
/Library/Frameworks/Python.framework/Versions/3.12/lib/python3.12/asyncio/runners.py:118: in run
    return self._loop.run_until_complete(task)
           ^^^^^^^^^^^^^^^^^^^^^^^^^^^^^^^^^^^
/Library/Frameworks/Python.framework/Versions/3.12/lib/python3.12/asyncio/base_events.py:687: in run_until_complete
    return future.result()
           ^^^^^^^^^^^^^^^
_ _ _ _ _ _ _ _ _ _ _ _ _ _ _ _ _ _ _ _ _ _ _ _ _ _ _ _ _ _ _ _ _ _ _ _ _ _ _ _ _ _ _ _ _ _ _ _ _ _ _ _ _ _ _ _ _ _ _ _ _ _ _ _ _ _ _ _ _ _ _ _ _ _ _ _ _ _ _ _ _ _ _ _ _ _ _ _ _ _ _ _ _ _ _ _ _ _ _ 

    async def test_database():
        repository = CostEstimatorRepositoryImpl()
    
        # Create real rate criteria
        rate_criteria = CostEstimatorRateCriteria(
            serviceCode="99214",
            providerIdentificationNumber="0004000317",
            placeOfService="11",
            serviceType="CPT4",
            networkId="58921",
            serviceLocationNumber="000761071",
            zipCode="85305",
            isOutofNetwork=False,
            providerSpecialtyCode="91017",
            providerType="HO"
        )
    
        try:
            result = await repository.get_rate(rate_criteria=rate_criteria)
            assert result is not None
            assert isinstance(result, (int, float))
        except Exception as e:
            # Database might be unavailable, which is acceptable for integration tests
>           assert "error" in str(e).lower() or "unavailable" in str(e).lower()
E           assert ('error' in "assert false\n +  where false = isinstance('na', (<class 'int'>, <class 'float'>))" or 'unavailable' in "assert false\n +  where false = isinstance('na', (<class 'int'>, <class 'float'>))")
E            +  where "assert false\n +  where false = isinstance('na', (<class 'int'>, <class 'float'>))" = <built-in method lower of str object at 0x1087f08b0>()
E            +    where <built-in method lower of str object at 0x1087f08b0> = "assert False\n +  where False = isinstance('NA', (<class 'int'>, <class 'float'>))".lower
E            +      where "assert False\n +  where False = isinstance('NA', (<class 'int'>, <class 'float'>))" = str(AssertionError("assert False\n +  where False = isinstance('NA', (<class 'int'>, <class 'float'>))"))
E            +  and   "assert false\n +  where false = isinstance('na', (<class 'int'>, <class 'float'>))" = <built-in method lower of str object at 0x1087f08b0>()
E            +    where <built-in method lower of str object at 0x1087f08b0> = "assert False\n +  where False = isinstance('NA', (<class 'int'>, <class 'float'>))".lower
E            +      where "assert False\n +  where False = isinstance('NA', (<class 'int'>, <class 'float'>))" = str(AssertionError("assert False\n +  where False = isinstance('NA', (<class 'int'>, <class 'float'>))"))

tests/test_integration_real.py:239: AssertionError
---------------------------------------------------------------------------------------- Captured stdout call ----------------------------------------------------------------------------------------
2025-07-22 13:14:59,709 | INFO | cost_estimator_calc_service | Async SpannerClient initialized for database: projects/anbc-hcb-dev/instances/provider-de/databases/cost-estimator-secure
2025-07-22 13:14:59,709 | INFO | cost_estimator_calc_service | Connection pool size: 10, Max workers: 20
2025-07-22 13:14:59,709 | INFO | cost_estimator_calc_service | Executing async query: SELECT MAX(RATE) AS RATE
FROM CET_CLAIM_BASED_AMOUNTS
WHERE
    PROVIDER_IDENTIFICATION_NBR = @provideridentificationnumber
    AND NETWORK_ID = @networkid
    AND PLACE_OF_SERVICE_CD = @placeofservice
    AND SERVICE_CD = @servicecd
    AND SERVICE_TYPE_CD = @servicetype
2025-07-22 13:14:59,709 | INFO | cost_estimator_calc_service | Query params: {'servicecd': '99214', 'provideridentificationnumber': '0004000317', 'placeofservice': '11', 'servicetype': 'CPT4', 'networkid': '58921', 'servicelocationnumber': '000761071'}
2025-07-22 13:15:26,890 | ERROR | cost_estimator_calc_service | Error executing async read-only query: Timeout of 30.0s exceeded, last exception: 503 Getting metadata from plugin failed with error: Reauthentication is needed. Please run `gcloud auth application-default login` to reauthenticate.
2025-07-22 13:15:26,890 | ERROR | cost_estimator_calc_service | Query: SELECT MAX(RATE) AS RATE
FROM CET_CLAIM_BASED_AMOUNTS
WHERE
    PROVIDER_IDENTIFICATION_NBR = @provideridentificationnumber
    AND NETWORK_ID = @networkid
    AND PLACE_OF_SERVICE_CD = @placeofservice
    AND SERVICE_CD = @servicecd
    AND SERVICE_TYPE_CD = @servicetype
2025-07-22 13:15:26,890 | ERROR | cost_estimator_calc_service | Params: {'servicecd': '99214', 'provideridentificationnumber': '0004000317', 'placeofservice': '11', 'servicetype': 'CPT4', 'networkid': '58921', 'servicelocationnumber': '000761071'}
2025-07-22 13:15:26,890 | ERROR | cost_estimator_calc_service | Exception type: <class 'google.api_core.exceptions.RetryError'>
2025-07-22 13:15:26,891 | ERROR | cost_estimator_calc_service | Exception details: Timeout of 30.0s exceeded, last exception: 503 Getting metadata from plugin failed with error: Reauthentication is needed. Please run `gcloud auth application-default login` to reauthenticate.
2025-07-22 13:15:26,891 | INFO | cost_estimator_calc_service | Claim-based rate result: []
2025-07-22 13:15:26,891 | INFO | cost_estimator_calc_service | No results found
2025-07-22 13:15:26,891 | INFO | cost_estimator_calc_service | No claim-based rate found, proceeding to get provider info
2025-07-22 13:15:26,891 | INFO | cost_estimator_calc_service | Executing async query: SELECT DISTINCT PROVIDER_BUSINESS_GROUP_NBR, PRODUCT_CD, RATING_SYSTEM_CD, EPDB_GEOGRAPHIC_AREA_CD
FROM CET_PROVIDERS
WHERE
    PROVIDER_IDENTIFICATION_NBR = @provideridentificationnumber
    AND NETWORK_ID = @networkid
    AND SERVICE_LOCATION_NBR = @servicelocationnumber
2025-07-22 13:15:26,891 | INFO | cost_estimator_calc_service | Query params: {'servicecd': '99214', 'provideridentificationnumber': '0004000317', 'placeofservice': '11', 'servicetype': 'CPT4', 'networkid': '58921', 'servicelocationnumber': '000761071'}
2025-07-22 13:15:57,468 | ERROR | cost_estimator_calc_service | Error executing async read-only query: Timeout of 30.0s exceeded, last exception: 503 Getting metadata from plugin failed with error: Reauthentication is needed. Please run `gcloud auth application-default login` to reauthenticate.
2025-07-22 13:15:57,469 | ERROR | cost_estimator_calc_service | Query: SELECT DISTINCT PROVIDER_BUSINESS_GROUP_NBR, PRODUCT_CD, RATING_SYSTEM_CD, EPDB_GEOGRAPHIC_AREA_CD
FROM CET_PROVIDERS
WHERE
    PROVIDER_IDENTIFICATION_NBR = @provideridentificationnumber
    AND NETWORK_ID = @networkid
    AND SERVICE_LOCATION_NBR = @servicelocationnumber
2025-07-22 13:15:57,469 | ERROR | cost_estimator_calc_service | Params: {'servicecd': '99214', 'provideridentificationnumber': '0004000317', 'placeofservice': '11', 'servicetype': 'CPT4', 'networkid': '58921', 'servicelocationnumber': '000761071'}
2025-07-22 13:15:57,469 | ERROR | cost_estimator_calc_service | Exception type: <class 'google.api_core.exceptions.RetryError'>
2025-07-22 13:15:57,469 | ERROR | cost_estimator_calc_service | Exception details: Timeout of 30.0s exceeded, last exception: 503 Getting metadata from plugin failed with error: Reauthentication is needed. Please run `gcloud auth application-default login` to reauthenticate.
2025-07-22 13:15:57,469 | INFO | cost_estimator_calc_service | Provider info result: []
2025-07-22 13:15:57,469 | INFO | cost_estimator_calc_service | No provider info results found
---------------------------------------------------------------------------------------- Captured stderr call ----------------------------------------------------------------------------------------
I0000 00:00:1753208099.710211 6461677 fork_posix.cc:71] Other threads are currently calling into gRPC, skipping fork() handlers
I0000 00:00:1753208129.898526 6461677 fork_posix.cc:71] Other threads are currently calling into gRPC, skipping fork() handlers
----------------------------------------------------------------------------------------- Captured log call ------------------------------------------------------------------------------------------
INFO     cost_estimator_calc_service:spanner_client.py:43 Async SpannerClient initialized for database: projects/anbc-hcb-dev/instances/provider-de/databases/cost-estimator-secure
INFO     cost_estimator_calc_service:spanner_client.py:46 Connection pool size: 10, Max workers: 20
INFO     cost_estimator_calc_service:spanner_client.py:69 Executing async query: SELECT MAX(RATE) AS RATE
FROM CET_CLAIM_BASED_AMOUNTS
WHERE
    PROVIDER_IDENTIFICATION_NBR = @provideridentificationnumber
    AND NETWORK_ID = @networkid
    AND PLACE_OF_SERVICE_CD = @placeofservice
    AND SERVICE_CD = @servicecd
    AND SERVICE_TYPE_CD = @servicetype
INFO     cost_estimator_calc_service:spanner_client.py:70 Query params: {'servicecd': '99214', 'provideridentificationnumber': '0004000317', 'placeofservice': '11', 'servicetype': 'CPT4', 'networkid': '58921', 'servicelocationnumber': '000761071'}
ERROR    grpc._plugin_wrapping:_plugin_wrapping.py:109 AuthMetadataPluginCallback "<google.auth.transport.grpc.AuthMetadataPlugin object at 0x10800ca40>" raised exception!
Traceback (most recent call last):
  File "/Users/N133723/Library/Python/3.12/lib/python/site-packages/grpc/_plugin_wrapping.py", line 105, in __call__
    self._metadata_plugin(
  File "/Users/N133723/Library/Python/3.12/lib/python/site-packages/google/auth/transport/grpc.py", line 95, in __call__
    callback(self._get_authorization_headers(context), None)
             ^^^^^^^^^^^^^^^^^^^^^^^^^^^^^^^^^^^^^^^^
  File "/Users/N133723/Library/Python/3.12/lib/python/site-packages/google/auth/transport/grpc.py", line 81, in _get_authorization_headers
    self._credentials.before_request(
  File "/Users/N133723/Library/Python/3.12/lib/python/site-packages/google/auth/credentials.py", line 239, in before_request
    self._blocking_refresh(request)
  File "/Users/N133723/Library/Python/3.12/lib/python/site-packages/google/auth/credentials.py", line 202, in _blocking_refresh
    self.refresh(request)
  File "/Users/N133723/Library/Python/3.12/lib/python/site-packages/google/oauth2/credentials.py", line 409, in refresh
    ) = reauth.refresh_grant(
        ^^^^^^^^^^^^^^^^^^^^^
  File "/Users/N133723/Library/Python/3.12/lib/python/site-packages/google/oauth2/reauth.py", line 349, in refresh_grant
    raise exceptions.RefreshError(
google.auth.exceptions.RefreshError: Reauthentication is needed. Please run `gcloud auth application-default login` to reauthenticate.
ERROR    grpc._plugin_wrapping:_plugin_wrapping.py:109 AuthMetadataPluginCallback "<google.auth.transport.grpc.AuthMetadataPlugin object at 0x10800ca40>" raised exception!
Traceback (most recent call last):
  File "/Users/N133723/Library/Python/3.12/lib/python/site-packages/grpc/_plugin_wrapping.py", line 105, in __call__
    self._metadata_plugin(
  File "/Users/N133723/Library/Python/3.12/lib/python/site-packages/google/auth/transport/grpc.py", line 95, in __call__
    callback(self._get_authorization_headers(context), None)
             ^^^^^^^^^^^^^^^^^^^^^^^^^^^^^^^^^^^^^^^^
  File "/Users/N133723/Library/Python/3.12/lib/python/site-packages/google/auth/transport/grpc.py", line 81, in _get_authorization_headers
    self._credentials.before_request(
  File "/Users/N133723/Library/Python/3.12/lib/python/site-packages/google/auth/credentials.py", line 239, in before_request
    self._blocking_refresh(request)
  File "/Users/N133723/Library/Python/3.12/lib/python/site-packages/google/auth/credentials.py", line 202, in _blocking_refresh
    self.refresh(request)
  File "/Users/N133723/Library/Python/3.12/lib/python/site-packages/google/oauth2/credentials.py", line 409, in refresh
    ) = reauth.refresh_grant(
        ^^^^^^^^^^^^^^^^^^^^^
  File "/Users/N133723/Library/Python/3.12/lib/python/site-packages/google/oauth2/reauth.py", line 349, in refresh_grant
    raise exceptions.RefreshError(
google.auth.exceptions.RefreshError: Reauthentication is needed. Please run `gcloud auth application-default login` to reauthenticate.
ERROR    grpc._plugin_wrapping:_plugin_wrapping.py:109 AuthMetadataPluginCallback "<google.auth.transport.grpc.AuthMetadataPlugin object at 0x10800ca40>" raised exception!
Traceback (most recent call last):
  File "/Users/N133723/Library/Python/3.12/lib/python/site-packages/grpc/_plugin_wrapping.py", line 105, in __call__
    self._metadata_plugin(
  File "/Users/N133723/Library/Python/3.12/lib/python/site-packages/google/auth/transport/grpc.py", line 95, in __call__
    callback(self._get_authorization_headers(context), None)
             ^^^^^^^^^^^^^^^^^^^^^^^^^^^^^^^^^^^^^^^^
  File "/Users/N133723/Library/Python/3.12/lib/python/site-packages/google/auth/transport/grpc.py", line 81, in _get_authorization_headers
    self._credentials.before_request(
  File "/Users/N133723/Library/Python/3.12/lib/python/site-packages/google/auth/credentials.py", line 239, in before_request
    self._blocking_refresh(request)
  File "/Users/N133723/Library/Python/3.12/lib/python/site-packages/google/auth/credentials.py", line 202, in _blocking_refresh
    self.refresh(request)
  File "/Users/N133723/Library/Python/3.12/lib/python/site-packages/google/oauth2/credentials.py", line 409, in refresh
    ) = reauth.refresh_grant(
        ^^^^^^^^^^^^^^^^^^^^^
  File "/Users/N133723/Library/Python/3.12/lib/python/site-packages/google/oauth2/reauth.py", line 349, in refresh_grant
    raise exceptions.RefreshError(
google.auth.exceptions.RefreshError: Reauthentication is needed. Please run `gcloud auth application-default login` to reauthenticate.
ERROR    grpc._plugin_wrapping:_plugin_wrapping.py:109 AuthMetadataPluginCallback "<google.auth.transport.grpc.AuthMetadataPlugin object at 0x10800ca40>" raised exception!
Traceback (most recent call last):
  File "/Users/N133723/Library/Python/3.12/lib/python/site-packages/grpc/_plugin_wrapping.py", line 105, in __call__
    self._metadata_plugin(
  File "/Users/N133723/Library/Python/3.12/lib/python/site-packages/google/auth/transport/grpc.py", line 95, in __call__
    callback(self._get_authorization_headers(context), None)
             ^^^^^^^^^^^^^^^^^^^^^^^^^^^^^^^^^^^^^^^^
  File "/Users/N133723/Library/Python/3.12/lib/python/site-packages/google/auth/transport/grpc.py", line 81, in _get_authorization_headers
    self._credentials.before_request(
  File "/Users/N133723/Library/Python/3.12/lib/python/site-packages/google/auth/credentials.py", line 239, in before_request
    self._blocking_refresh(request)
  File "/Users/N133723/Library/Python/3.12/lib/python/site-packages/google/auth/credentials.py", line 202, in _blocking_refresh
    self.refresh(request)
  File "/Users/N133723/Library/Python/3.12/lib/python/site-packages/google/oauth2/credentials.py", line 409, in refresh
    ) = reauth.refresh_grant(
        ^^^^^^^^^^^^^^^^^^^^^
  File "/Users/N133723/Library/Python/3.12/lib/python/site-packages/google/oauth2/reauth.py", line 349, in refresh_grant
    raise exceptions.RefreshError(
google.auth.exceptions.RefreshError: Reauthentication is needed. Please run `gcloud auth application-default login` to reauthenticate.
ERROR    grpc._plugin_wrapping:_plugin_wrapping.py:109 AuthMetadataPluginCallback "<google.auth.transport.grpc.AuthMetadataPlugin object at 0x10800ca40>" raised exception!
Traceback (most recent call last):
  File "/Users/N133723/Library/Python/3.12/lib/python/site-packages/grpc/_plugin_wrapping.py", line 105, in __call__
    self._metadata_plugin(
  File "/Users/N133723/Library/Python/3.12/lib/python/site-packages/google/auth/transport/grpc.py", line 95, in __call__
    callback(self._get_authorization_headers(context), None)
             ^^^^^^^^^^^^^^^^^^^^^^^^^^^^^^^^^^^^^^^^
  File "/Users/N133723/Library/Python/3.12/lib/python/site-packages/google/auth/transport/grpc.py", line 81, in _get_authorization_headers
    self._credentials.before_request(
  File "/Users/N133723/Library/Python/3.12/lib/python/site-packages/google/auth/credentials.py", line 239, in before_request
    self._blocking_refresh(request)
  File "/Users/N133723/Library/Python/3.12/lib/python/site-packages/google/auth/credentials.py", line 202, in _blocking_refresh
    self.refresh(request)
  File "/Users/N133723/Library/Python/3.12/lib/python/site-packages/google/oauth2/credentials.py", line 409, in refresh
    ) = reauth.refresh_grant(
        ^^^^^^^^^^^^^^^^^^^^^
  File "/Users/N133723/Library/Python/3.12/lib/python/site-packages/google/oauth2/reauth.py", line 349, in refresh_grant
    raise exceptions.RefreshError(
google.auth.exceptions.RefreshError: Reauthentication is needed. Please run `gcloud auth application-default login` to reauthenticate.
ERROR    grpc._plugin_wrapping:_plugin_wrapping.py:109 AuthMetadataPluginCallback "<google.auth.transport.grpc.AuthMetadataPlugin object at 0x10800ca40>" raised exception!
Traceback (most recent call last):
  File "/Users/N133723/Library/Python/3.12/lib/python/site-packages/grpc/_plugin_wrapping.py", line 105, in __call__
    self._metadata_plugin(
  File "/Users/N133723/Library/Python/3.12/lib/python/site-packages/google/auth/transport/grpc.py", line 95, in __call__
    callback(self._get_authorization_headers(context), None)
             ^^^^^^^^^^^^^^^^^^^^^^^^^^^^^^^^^^^^^^^^
  File "/Users/N133723/Library/Python/3.12/lib/python/site-packages/google/auth/transport/grpc.py", line 81, in _get_authorization_headers
    self._credentials.before_request(
  File "/Users/N133723/Library/Python/3.12/lib/python/site-packages/google/auth/credentials.py", line 239, in before_request
    self._blocking_refresh(request)
  File "/Users/N133723/Library/Python/3.12/lib/python/site-packages/google/auth/credentials.py", line 202, in _blocking_refresh
    self.refresh(request)
  File "/Users/N133723/Library/Python/3.12/lib/python/site-packages/google/oauth2/credentials.py", line 409, in refresh
    ) = reauth.refresh_grant(
        ^^^^^^^^^^^^^^^^^^^^^
  File "/Users/N133723/Library/Python/3.12/lib/python/site-packages/google/oauth2/reauth.py", line 349, in refresh_grant
    raise exceptions.RefreshError(
google.auth.exceptions.RefreshError: Reauthentication is needed. Please run `gcloud auth application-default login` to reauthenticate.
ERROR    grpc._plugin_wrapping:_plugin_wrapping.py:109 AuthMetadataPluginCallback "<google.auth.transport.grpc.AuthMetadataPlugin object at 0x10800ca40>" raised exception!
Traceback (most recent call last):
  File "/Users/N133723/Library/Python/3.12/lib/python/site-packages/grpc/_plugin_wrapping.py", line 105, in __call__
    self._metadata_plugin(
  File "/Users/N133723/Library/Python/3.12/lib/python/site-packages/google/auth/transport/grpc.py", line 95, in __call__
    callback(self._get_authorization_headers(context), None)
             ^^^^^^^^^^^^^^^^^^^^^^^^^^^^^^^^^^^^^^^^
  File "/Users/N133723/Library/Python/3.12/lib/python/site-packages/google/auth/transport/grpc.py", line 81, in _get_authorization_headers
    self._credentials.before_request(
  File "/Users/N133723/Library/Python/3.12/lib/python/site-packages/google/auth/credentials.py", line 239, in before_request
    self._blocking_refresh(request)
  File "/Users/N133723/Library/Python/3.12/lib/python/site-packages/google/auth/credentials.py", line 202, in _blocking_refresh
    self.refresh(request)
  File "/Users/N133723/Library/Python/3.12/lib/python/site-packages/google/oauth2/credentials.py", line 409, in refresh
    ) = reauth.refresh_grant(
        ^^^^^^^^^^^^^^^^^^^^^
  File "/Users/N133723/Library/Python/3.12/lib/python/site-packages/google/oauth2/reauth.py", line 349, in refresh_grant
    raise exceptions.RefreshError(
google.auth.exceptions.RefreshError: Reauthentication is needed. Please run `gcloud auth application-default login` to reauthenticate.
ERROR    grpc._plugin_wrapping:_plugin_wrapping.py:109 AuthMetadataPluginCallback "<google.auth.transport.grpc.AuthMetadataPlugin object at 0x10800ca40>" raised exception!
Traceback (most recent call last):
  File "/Users/N133723/Library/Python/3.12/lib/python/site-packages/grpc/_plugin_wrapping.py", line 105, in __call__
    self._metadata_plugin(
  File "/Users/N133723/Library/Python/3.12/lib/python/site-packages/google/auth/transport/grpc.py", line 95, in __call__
    callback(self._get_authorization_headers(context), None)
             ^^^^^^^^^^^^^^^^^^^^^^^^^^^^^^^^^^^^^^^^
  File "/Users/N133723/Library/Python/3.12/lib/python/site-packages/google/auth/transport/grpc.py", line 81, in _get_authorization_headers
    self._credentials.before_request(
  File "/Users/N133723/Library/Python/3.12/lib/python/site-packages/google/auth/credentials.py", line 239, in before_request
    self._blocking_refresh(request)
  File "/Users/N133723/Library/Python/3.12/lib/python/site-packages/google/auth/credentials.py", line 202, in _blocking_refresh
    self.refresh(request)
  File "/Users/N133723/Library/Python/3.12/lib/python/site-packages/google/oauth2/credentials.py", line 409, in refresh
    ) = reauth.refresh_grant(
        ^^^^^^^^^^^^^^^^^^^^^
  File "/Users/N133723/Library/Python/3.12/lib/python/site-packages/google/oauth2/reauth.py", line 349, in refresh_grant
    raise exceptions.RefreshError(
google.auth.exceptions.RefreshError: Reauthentication is needed. Please run `gcloud auth application-default login` to reauthenticate.
ERROR    grpc._plugin_wrapping:_plugin_wrapping.py:109 AuthMetadataPluginCallback "<google.auth.transport.grpc.AuthMetadataPlugin object at 0x10800ca40>" raised exception!
Traceback (most recent call last):
  File "/Users/N133723/Library/Python/3.12/lib/python/site-packages/grpc/_plugin_wrapping.py", line 105, in __call__
    self._metadata_plugin(
  File "/Users/N133723/Library/Python/3.12/lib/python/site-packages/google/auth/transport/grpc.py", line 95, in __call__
    callback(self._get_authorization_headers(context), None)
             ^^^^^^^^^^^^^^^^^^^^^^^^^^^^^^^^^^^^^^^^
  File "/Users/N133723/Library/Python/3.12/lib/python/site-packages/google/auth/transport/grpc.py", line 81, in _get_authorization_headers
    self._credentials.before_request(
  File "/Users/N133723/Library/Python/3.12/lib/python/site-packages/google/auth/credentials.py", line 239, in before_request
    self._blocking_refresh(request)
  File "/Users/N133723/Library/Python/3.12/lib/python/site-packages/google/auth/credentials.py", line 202, in _blocking_refresh
    self.refresh(request)
  File "/Users/N133723/Library/Python/3.12/lib/python/site-packages/google/oauth2/credentials.py", line 409, in refresh
    ) = reauth.refresh_grant(
        ^^^^^^^^^^^^^^^^^^^^^
  File "/Users/N133723/Library/Python/3.12/lib/python/site-packages/google/oauth2/reauth.py", line 349, in refresh_grant
    raise exceptions.RefreshError(
google.auth.exceptions.RefreshError: Reauthentication is needed. Please run `gcloud auth application-default login` to reauthenticate.
ERROR    grpc._plugin_wrapping:_plugin_wrapping.py:109 AuthMetadataPluginCallback "<google.auth.transport.grpc.AuthMetadataPlugin object at 0x10800ca40>" raised exception!
Traceback (most recent call last):
  File "/Users/N133723/Library/Python/3.12/lib/python/site-packages/grpc/_plugin_wrapping.py", line 105, in __call__
    self._metadata_plugin(
  File "/Users/N133723/Library/Python/3.12/lib/python/site-packages/google/auth/transport/grpc.py", line 95, in __call__
    callback(self._get_authorization_headers(context), None)
             ^^^^^^^^^^^^^^^^^^^^^^^^^^^^^^^^^^^^^^^^
  File "/Users/N133723/Library/Python/3.12/lib/python/site-packages/google/auth/transport/grpc.py", line 81, in _get_authorization_headers
    self._credentials.before_request(
  File "/Users/N133723/Library/Python/3.12/lib/python/site-packages/google/auth/credentials.py", line 239, in before_request
    self._blocking_refresh(request)
  File "/Users/N133723/Library/Python/3.12/lib/python/site-packages/google/auth/credentials.py", line 202, in _blocking_refresh
    self.refresh(request)
  File "/Users/N133723/Library/Python/3.12/lib/python/site-packages/google/oauth2/credentials.py", line 409, in refresh
    ) = reauth.refresh_grant(
        ^^^^^^^^^^^^^^^^^^^^^
  File "/Users/N133723/Library/Python/3.12/lib/python/site-packages/google/oauth2/reauth.py", line 349, in refresh_grant
    raise exceptions.RefreshError(
google.auth.exceptions.RefreshError: Reauthentication is needed. Please run `gcloud auth application-default login` to reauthenticate.
ERROR    grpc._plugin_wrapping:_plugin_wrapping.py:109 AuthMetadataPluginCallback "<google.auth.transport.grpc.AuthMetadataPlugin object at 0x10800ca40>" raised exception!
Traceback (most recent call last):
  File "/Users/N133723/Library/Python/3.12/lib/python/site-packages/grpc/_plugin_wrapping.py", line 105, in __call__
    self._metadata_plugin(
  File "/Users/N133723/Library/Python/3.12/lib/python/site-packages/google/auth/transport/grpc.py", line 95, in __call__
    callback(self._get_authorization_headers(context), None)
             ^^^^^^^^^^^^^^^^^^^^^^^^^^^^^^^^^^^^^^^^
  File "/Users/N133723/Library/Python/3.12/lib/python/site-packages/google/auth/transport/grpc.py", line 81, in _get_authorization_headers
    self._credentials.before_request(
  File "/Users/N133723/Library/Python/3.12/lib/python/site-packages/google/auth/credentials.py", line 239, in before_request
    self._blocking_refresh(request)
  File "/Users/N133723/Library/Python/3.12/lib/python/site-packages/google/auth/credentials.py", line 202, in _blocking_refresh
    self.refresh(request)
  File "/Users/N133723/Library/Python/3.12/lib/python/site-packages/google/oauth2/credentials.py", line 409, in refresh
    ) = reauth.refresh_grant(
        ^^^^^^^^^^^^^^^^^^^^^
  File "/Users/N133723/Library/Python/3.12/lib/python/site-packages/google/oauth2/reauth.py", line 349, in refresh_grant
    raise exceptions.RefreshError(
google.auth.exceptions.RefreshError: Reauthentication is needed. Please run `gcloud auth application-default login` to reauthenticate.
ERROR    grpc._plugin_wrapping:_plugin_wrapping.py:109 AuthMetadataPluginCallback "<google.auth.transport.grpc.AuthMetadataPlugin object at 0x10800ca40>" raised exception!
Traceback (most recent call last):
  File "/Users/N133723/Library/Python/3.12/lib/python/site-packages/grpc/_plugin_wrapping.py", line 105, in __call__
    self._metadata_plugin(
  File "/Users/N133723/Library/Python/3.12/lib/python/site-packages/google/auth/transport/grpc.py", line 95, in __call__
    callback(self._get_authorization_headers(context), None)
             ^^^^^^^^^^^^^^^^^^^^^^^^^^^^^^^^^^^^^^^^
  File "/Users/N133723/Library/Python/3.12/lib/python/site-packages/google/auth/transport/grpc.py", line 81, in _get_authorization_headers
    self._credentials.before_request(
  File "/Users/N133723/Library/Python/3.12/lib/python/site-packages/google/auth/credentials.py", line 239, in before_request
    self._blocking_refresh(request)
  File "/Users/N133723/Library/Python/3.12/lib/python/site-packages/google/auth/credentials.py", line 202, in _blocking_refresh
    self.refresh(request)
  File "/Users/N133723/Library/Python/3.12/lib/python/site-packages/google/oauth2/credentials.py", line 409, in refresh
    ) = reauth.refresh_grant(
        ^^^^^^^^^^^^^^^^^^^^^
  File "/Users/N133723/Library/Python/3.12/lib/python/site-packages/google/oauth2/reauth.py", line 349, in refresh_grant
    raise exceptions.RefreshError(
google.auth.exceptions.RefreshError: Reauthentication is needed. Please run `gcloud auth application-default login` to reauthenticate.
ERROR    grpc._plugin_wrapping:_plugin_wrapping.py:109 AuthMetadataPluginCallback "<google.auth.transport.grpc.AuthMetadataPlugin object at 0x10800ca40>" raised exception!
Traceback (most recent call last):
  File "/Users/N133723/Library/Python/3.12/lib/python/site-packages/grpc/_plugin_wrapping.py", line 105, in __call__
    self._metadata_plugin(
  File "/Users/N133723/Library/Python/3.12/lib/python/site-packages/google/auth/transport/grpc.py", line 95, in __call__
    callback(self._get_authorization_headers(context), None)
             ^^^^^^^^^^^^^^^^^^^^^^^^^^^^^^^^^^^^^^^^
  File "/Users/N133723/Library/Python/3.12/lib/python/site-packages/google/auth/transport/grpc.py", line 81, in _get_authorization_headers
    self._credentials.before_request(
  File "/Users/N133723/Library/Python/3.12/lib/python/site-packages/google/auth/credentials.py", line 239, in before_request
    self._blocking_refresh(request)
  File "/Users/N133723/Library/Python/3.12/lib/python/site-packages/google/auth/credentials.py", line 202, in _blocking_refresh
    self.refresh(request)
  File "/Users/N133723/Library/Python/3.12/lib/python/site-packages/google/oauth2/credentials.py", line 409, in refresh
    ) = reauth.refresh_grant(
        ^^^^^^^^^^^^^^^^^^^^^
  File "/Users/N133723/Library/Python/3.12/lib/python/site-packages/google/oauth2/reauth.py", line 349, in refresh_grant
    raise exceptions.RefreshError(
google.auth.exceptions.RefreshError: Reauthentication is needed. Please run `gcloud auth application-default login` to reauthenticate.
ERROR    grpc._plugin_wrapping:_plugin_wrapping.py:109 AuthMetadataPluginCallback "<google.auth.transport.grpc.AuthMetadataPlugin object at 0x10800ca40>" raised exception!
Traceback (most recent call last):
  File "/Users/N133723/Library/Python/3.12/lib/python/site-packages/grpc/_plugin_wrapping.py", line 105, in __call__
    self._metadata_plugin(
  File "/Users/N133723/Library/Python/3.12/lib/python/site-packages/google/auth/transport/grpc.py", line 95, in __call__
    callback(self._get_authorization_headers(context), None)
             ^^^^^^^^^^^^^^^^^^^^^^^^^^^^^^^^^^^^^^^^
  File "/Users/N133723/Library/Python/3.12/lib/python/site-packages/google/auth/transport/grpc.py", line 81, in _get_authorization_headers
    self._credentials.before_request(
  File "/Users/N133723/Library/Python/3.12/lib/python/site-packages/google/auth/credentials.py", line 239, in before_request
    self._blocking_refresh(request)
  File "/Users/N133723/Library/Python/3.12/lib/python/site-packages/google/auth/credentials.py", line 202, in _blocking_refresh
    self.refresh(request)
  File "/Users/N133723/Library/Python/3.12/lib/python/site-packages/google/oauth2/credentials.py", line 409, in refresh
    ) = reauth.refresh_grant(
        ^^^^^^^^^^^^^^^^^^^^^
  File "/Users/N133723/Library/Python/3.12/lib/python/site-packages/google/oauth2/reauth.py", line 349, in refresh_grant
    raise exceptions.RefreshError(
google.auth.exceptions.RefreshError: Reauthentication is needed. Please run `gcloud auth application-default login` to reauthenticate.
ERROR    grpc._plugin_wrapping:_plugin_wrapping.py:109 AuthMetadataPluginCallback "<google.auth.transport.grpc.AuthMetadataPlugin object at 0x10800ca40>" raised exception!
Traceback (most recent call last):
  File "/Users/N133723/Library/Python/3.12/lib/python/site-packages/grpc/_plugin_wrapping.py", line 105, in __call__
    self._metadata_plugin(
  File "/Users/N133723/Library/Python/3.12/lib/python/site-packages/google/auth/transport/grpc.py", line 95, in __call__
    callback(self._get_authorization_headers(context), None)
             ^^^^^^^^^^^^^^^^^^^^^^^^^^^^^^^^^^^^^^^^
  File "/Users/N133723/Library/Python/3.12/lib/python/site-packages/google/auth/transport/grpc.py", line 81, in _get_authorization_headers
    self._credentials.before_request(
  File "/Users/N133723/Library/Python/3.12/lib/python/site-packages/google/auth/credentials.py", line 239, in before_request
    self._blocking_refresh(request)
  File "/Users/N133723/Library/Python/3.12/lib/python/site-packages/google/auth/credentials.py", line 202, in _blocking_refresh
    self.refresh(request)
  File "/Users/N133723/Library/Python/3.12/lib/python/site-packages/google/oauth2/credentials.py", line 409, in refresh
    ) = reauth.refresh_grant(
        ^^^^^^^^^^^^^^^^^^^^^
  File "/Users/N133723/Library/Python/3.12/lib/python/site-packages/google/oauth2/reauth.py", line 349, in refresh_grant
    raise exceptions.RefreshError(
google.auth.exceptions.RefreshError: Reauthentication is needed. Please run `gcloud auth application-default login` to reauthenticate.
ERROR    grpc._plugin_wrapping:_plugin_wrapping.py:109 AuthMetadataPluginCallback "<google.auth.transport.grpc.AuthMetadataPlugin object at 0x10800ca40>" raised exception!
Traceback (most recent call last):
  File "/Users/N133723/Library/Python/3.12/lib/python/site-packages/grpc/_plugin_wrapping.py", line 105, in __call__
    self._metadata_plugin(
  File "/Users/N133723/Library/Python/3.12/lib/python/site-packages/google/auth/transport/grpc.py", line 95, in __call__
    callback(self._get_authorization_headers(context), None)
             ^^^^^^^^^^^^^^^^^^^^^^^^^^^^^^^^^^^^^^^^
  File "/Users/N133723/Library/Python/3.12/lib/python/site-packages/google/auth/transport/grpc.py", line 81, in _get_authorization_headers
    self._credentials.before_request(
  File "/Users/N133723/Library/Python/3.12/lib/python/site-packages/google/auth/credentials.py", line 239, in before_request
    self._blocking_refresh(request)
  File "/Users/N133723/Library/Python/3.12/lib/python/site-packages/google/auth/credentials.py", line 202, in _blocking_refresh
    self.refresh(request)
  File "/Users/N133723/Library/Python/3.12/lib/python/site-packages/google/oauth2/credentials.py", line 409, in refresh
    ) = reauth.refresh_grant(
        ^^^^^^^^^^^^^^^^^^^^^
  File "/Users/N133723/Library/Python/3.12/lib/python/site-packages/google/oauth2/reauth.py", line 349, in refresh_grant
    raise exceptions.RefreshError(
google.auth.exceptions.RefreshError: Reauthentication is needed. Please run `gcloud auth application-default login` to reauthenticate.
ERROR    cost_estimator_calc_service:spanner_client.py:85 Error executing async read-only query: Timeout of 30.0s exceeded, last exception: 503 Getting metadata from plugin failed with error: Reauthentication is needed. Please run `gcloud auth application-default login` to reauthenticate.
ERROR    cost_estimator_calc_service:spanner_client.py:86 Query: SELECT MAX(RATE) AS RATE
FROM CET_CLAIM_BASED_AMOUNTS
WHERE
    PROVIDER_IDENTIFICATION_NBR = @provideridentificationnumber
    AND NETWORK_ID = @networkid
    AND PLACE_OF_SERVICE_CD = @placeofservice
    AND SERVICE_CD = @servicecd
    AND SERVICE_TYPE_CD = @servicetype
ERROR    cost_estimator_calc_service:spanner_client.py:87 Params: {'servicecd': '99214', 'provideridentificationnumber': '0004000317', 'placeofservice': '11', 'servicetype': 'CPT4', 'networkid': '58921', 'servicelocationnumber': '000761071'}
ERROR    cost_estimator_calc_service:spanner_client.py:88 Exception type: <class 'google.api_core.exceptions.RetryError'>
ERROR    cost_estimator_calc_service:spanner_client.py:89 Exception details: Timeout of 30.0s exceeded, last exception: 503 Getting metadata from plugin failed with error: Reauthentication is needed. Please run `gcloud auth application-default login` to reauthenticate.
INFO     cost_estimator_calc_service:cost_estimator_repository_impl.py:58 Claim-based rate result: []
INFO     cost_estimator_calc_service:cost_estimator_repository_impl.py:199 No results found
INFO     cost_estimator_calc_service:cost_estimator_repository_impl.py:66 No claim-based rate found, proceeding to get provider info
INFO     cost_estimator_calc_service:spanner_client.py:69 Executing async query: SELECT DISTINCT PROVIDER_BUSINESS_GROUP_NBR, PRODUCT_CD, RATING_SYSTEM_CD, EPDB_GEOGRAPHIC_AREA_CD
FROM CET_PROVIDERS
WHERE
    PROVIDER_IDENTIFICATION_NBR = @provideridentificationnumber
    AND NETWORK_ID = @networkid
    AND SERVICE_LOCATION_NBR = @servicelocationnumber
INFO     cost_estimator_calc_service:spanner_client.py:70 Query params: {'servicecd': '99214', 'provideridentificationnumber': '0004000317', 'placeofservice': '11', 'servicetype': 'CPT4', 'networkid': '58921', 'servicelocationnumber': '000761071'}
ERROR    grpc._plugin_wrapping:_plugin_wrapping.py:109 AuthMetadataPluginCallback "<google.auth.transport.grpc.AuthMetadataPlugin object at 0x108059340>" raised exception!
Traceback (most recent call last):
  File "/Users/N133723/Library/Python/3.12/lib/python/site-packages/grpc/_plugin_wrapping.py", line 105, in __call__
    self._metadata_plugin(
  File "/Users/N133723/Library/Python/3.12/lib/python/site-packages/google/auth/transport/grpc.py", line 95, in __call__
    callback(self._get_authorization_headers(context), None)
             ^^^^^^^^^^^^^^^^^^^^^^^^^^^^^^^^^^^^^^^^
  File "/Users/N133723/Library/Python/3.12/lib/python/site-packages/google/auth/transport/grpc.py", line 81, in _get_authorization_headers
    self._credentials.before_request(
  File "/Users/N133723/Library/Python/3.12/lib/python/site-packages/google/auth/credentials.py", line 239, in before_request
    self._blocking_refresh(request)
  File "/Users/N133723/Library/Python/3.12/lib/python/site-packages/google/auth/credentials.py", line 202, in _blocking_refresh
    self.refresh(request)
  File "/Users/N133723/Library/Python/3.12/lib/python/site-packages/google/oauth2/credentials.py", line 409, in refresh
    ) = reauth.refresh_grant(
        ^^^^^^^^^^^^^^^^^^^^^
  File "/Users/N133723/Library/Python/3.12/lib/python/site-packages/google/oauth2/reauth.py", line 349, in refresh_grant
    raise exceptions.RefreshError(
google.auth.exceptions.RefreshError: Reauthentication is needed. Please run `gcloud auth application-default login` to reauthenticate.
ERROR    grpc._plugin_wrapping:_plugin_wrapping.py:109 AuthMetadataPluginCallback "<google.auth.transport.grpc.AuthMetadataPlugin object at 0x108059340>" raised exception!
Traceback (most recent call last):
  File "/Users/N133723/Library/Python/3.12/lib/python/site-packages/grpc/_plugin_wrapping.py", line 105, in __call__
    self._metadata_plugin(
  File "/Users/N133723/Library/Python/3.12/lib/python/site-packages/google/auth/transport/grpc.py", line 95, in __call__
    callback(self._get_authorization_headers(context), None)
             ^^^^^^^^^^^^^^^^^^^^^^^^^^^^^^^^^^^^^^^^
  File "/Users/N133723/Library/Python/3.12/lib/python/site-packages/google/auth/transport/grpc.py", line 81, in _get_authorization_headers
    self._credentials.before_request(
  File "/Users/N133723/Library/Python/3.12/lib/python/site-packages/google/auth/credentials.py", line 239, in before_request
    self._blocking_refresh(request)
  File "/Users/N133723/Library/Python/3.12/lib/python/site-packages/google/auth/credentials.py", line 202, in _blocking_refresh
    self.refresh(request)
  File "/Users/N133723/Library/Python/3.12/lib/python/site-packages/google/oauth2/credentials.py", line 409, in refresh
    ) = reauth.refresh_grant(
        ^^^^^^^^^^^^^^^^^^^^^
  File "/Users/N133723/Library/Python/3.12/lib/python/site-packages/google/oauth2/reauth.py", line 349, in refresh_grant
    raise exceptions.RefreshError(
google.auth.exceptions.RefreshError: Reauthentication is needed. Please run `gcloud auth application-default login` to reauthenticate.
ERROR    grpc._plugin_wrapping:_plugin_wrapping.py:109 AuthMetadataPluginCallback "<google.auth.transport.grpc.AuthMetadataPlugin object at 0x108059340>" raised exception!
Traceback (most recent call last):
  File "/Users/N133723/Library/Python/3.12/lib/python/site-packages/grpc/_plugin_wrapping.py", line 105, in __call__
    self._metadata_plugin(
  File "/Users/N133723/Library/Python/3.12/lib/python/site-packages/google/auth/transport/grpc.py", line 95, in __call__
    callback(self._get_authorization_headers(context), None)
             ^^^^^^^^^^^^^^^^^^^^^^^^^^^^^^^^^^^^^^^^
  File "/Users/N133723/Library/Python/3.12/lib/python/site-packages/google/auth/transport/grpc.py", line 81, in _get_authorization_headers
    self._credentials.before_request(
  File "/Users/N133723/Library/Python/3.12/lib/python/site-packages/google/auth/credentials.py", line 239, in before_request
    self._blocking_refresh(request)
  File "/Users/N133723/Library/Python/3.12/lib/python/site-packages/google/auth/credentials.py", line 202, in _blocking_refresh
    self.refresh(request)
  File "/Users/N133723/Library/Python/3.12/lib/python/site-packages/google/oauth2/credentials.py", line 409, in refresh
    ) = reauth.refresh_grant(
        ^^^^^^^^^^^^^^^^^^^^^
  File "/Users/N133723/Library/Python/3.12/lib/python/site-packages/google/oauth2/reauth.py", line 349, in refresh_grant
    raise exceptions.RefreshError(
google.auth.exceptions.RefreshError: Reauthentication is needed. Please run `gcloud auth application-default login` to reauthenticate.
ERROR    grpc._plugin_wrapping:_plugin_wrapping.py:109 AuthMetadataPluginCallback "<google.auth.transport.grpc.AuthMetadataPlugin object at 0x108059340>" raised exception!
Traceback (most recent call last):
  File "/Users/N133723/Library/Python/3.12/lib/python/site-packages/grpc/_plugin_wrapping.py", line 105, in __call__
    self._metadata_plugin(
  File "/Users/N133723/Library/Python/3.12/lib/python/site-packages/google/auth/transport/grpc.py", line 95, in __call__
    callback(self._get_authorization_headers(context), None)
             ^^^^^^^^^^^^^^^^^^^^^^^^^^^^^^^^^^^^^^^^
  File "/Users/N133723/Library/Python/3.12/lib/python/site-packages/google/auth/transport/grpc.py", line 81, in _get_authorization_headers
    self._credentials.before_request(
  File "/Users/N133723/Library/Python/3.12/lib/python/site-packages/google/auth/credentials.py", line 239, in before_request
    self._blocking_refresh(request)
  File "/Users/N133723/Library/Python/3.12/lib/python/site-packages/google/auth/credentials.py", line 202, in _blocking_refresh
    self.refresh(request)
  File "/Users/N133723/Library/Python/3.12/lib/python/site-packages/google/oauth2/credentials.py", line 409, in refresh
    ) = reauth.refresh_grant(
        ^^^^^^^^^^^^^^^^^^^^^
  File "/Users/N133723/Library/Python/3.12/lib/python/site-packages/google/oauth2/reauth.py", line 349, in refresh_grant
    raise exceptions.RefreshError(
google.auth.exceptions.RefreshError: Reauthentication is needed. Please run `gcloud auth application-default login` to reauthenticate.
ERROR    grpc._plugin_wrapping:_plugin_wrapping.py:109 AuthMetadataPluginCallback "<google.auth.transport.grpc.AuthMetadataPlugin object at 0x108059340>" raised exception!
Traceback (most recent call last):
  File "/Users/N133723/Library/Python/3.12/lib/python/site-packages/grpc/_plugin_wrapping.py", line 105, in __call__
    self._metadata_plugin(
  File "/Users/N133723/Library/Python/3.12/lib/python/site-packages/google/auth/transport/grpc.py", line 95, in __call__
    callback(self._get_authorization_headers(context), None)
             ^^^^^^^^^^^^^^^^^^^^^^^^^^^^^^^^^^^^^^^^
  File "/Users/N133723/Library/Python/3.12/lib/python/site-packages/google/auth/transport/grpc.py", line 81, in _get_authorization_headers
    self._credentials.before_request(
  File "/Users/N133723/Library/Python/3.12/lib/python/site-packages/google/auth/credentials.py", line 239, in before_request
    self._blocking_refresh(request)
  File "/Users/N133723/Library/Python/3.12/lib/python/site-packages/google/auth/credentials.py", line 202, in _blocking_refresh
    self.refresh(request)
  File "/Users/N133723/Library/Python/3.12/lib/python/site-packages/google/oauth2/credentials.py", line 409, in refresh
    ) = reauth.refresh_grant(
        ^^^^^^^^^^^^^^^^^^^^^
  File "/Users/N133723/Library/Python/3.12/lib/python/site-packages/google/oauth2/reauth.py", line 349, in refresh_grant
    raise exceptions.RefreshError(
google.auth.exceptions.RefreshError: Reauthentication is needed. Please run `gcloud auth application-default login` to reauthenticate.
ERROR    grpc._plugin_wrapping:_plugin_wrapping.py:109 AuthMetadataPluginCallback "<google.auth.transport.grpc.AuthMetadataPlugin object at 0x108059340>" raised exception!
Traceback (most recent call last):
  File "/Users/N133723/Library/Python/3.12/lib/python/site-packages/grpc/_plugin_wrapping.py", line 105, in __call__
    self._metadata_plugin(
  File "/Users/N133723/Library/Python/3.12/lib/python/site-packages/google/auth/transport/grpc.py", line 95, in __call__
    callback(self._get_authorization_headers(context), None)
             ^^^^^^^^^^^^^^^^^^^^^^^^^^^^^^^^^^^^^^^^
  File "/Users/N133723/Library/Python/3.12/lib/python/site-packages/google/auth/transport/grpc.py", line 81, in _get_authorization_headers
    self._credentials.before_request(
  File "/Users/N133723/Library/Python/3.12/lib/python/site-packages/google/auth/credentials.py", line 239, in before_request
    self._blocking_refresh(request)
  File "/Users/N133723/Library/Python/3.12/lib/python/site-packages/google/auth/credentials.py", line 202, in _blocking_refresh
    self.refresh(request)
  File "/Users/N133723/Library/Python/3.12/lib/python/site-packages/google/oauth2/credentials.py", line 409, in refresh
    ) = reauth.refresh_grant(
        ^^^^^^^^^^^^^^^^^^^^^
  File "/Users/N133723/Library/Python/3.12/lib/python/site-packages/google/oauth2/reauth.py", line 349, in refresh_grant
    raise exceptions.RefreshError(
google.auth.exceptions.RefreshError: Reauthentication is needed. Please run `gcloud auth application-default login` to reauthenticate.
ERROR    grpc._plugin_wrapping:_plugin_wrapping.py:109 AuthMetadataPluginCallback "<google.auth.transport.grpc.AuthMetadataPlugin object at 0x108059340>" raised exception!
Traceback (most recent call last):
  File "/Users/N133723/Library/Python/3.12/lib/python/site-packages/grpc/_plugin_wrapping.py", line 105, in __call__
    self._metadata_plugin(
  File "/Users/N133723/Library/Python/3.12/lib/python/site-packages/google/auth/transport/grpc.py", line 95, in __call__
    callback(self._get_authorization_headers(context), None)
             ^^^^^^^^^^^^^^^^^^^^^^^^^^^^^^^^^^^^^^^^
  File "/Users/N133723/Library/Python/3.12/lib/python/site-packages/google/auth/transport/grpc.py", line 81, in _get_authorization_headers
    self._credentials.before_request(
  File "/Users/N133723/Library/Python/3.12/lib/python/site-packages/google/auth/credentials.py", line 239, in before_request
    self._blocking_refresh(request)
  File "/Users/N133723/Library/Python/3.12/lib/python/site-packages/google/auth/credentials.py", line 202, in _blocking_refresh
    self.refresh(request)
  File "/Users/N133723/Library/Python/3.12/lib/python/site-packages/google/oauth2/credentials.py", line 409, in refresh
    ) = reauth.refresh_grant(
        ^^^^^^^^^^^^^^^^^^^^^
  File "/Users/N133723/Library/Python/3.12/lib/python/site-packages/google/oauth2/reauth.py", line 349, in refresh_grant
    raise exceptions.RefreshError(
google.auth.exceptions.RefreshError: Reauthentication is needed. Please run `gcloud auth application-default login` to reauthenticate.
ERROR    grpc._plugin_wrapping:_plugin_wrapping.py:109 AuthMetadataPluginCallback "<google.auth.transport.grpc.AuthMetadataPlugin object at 0x108059340>" raised exception!
Traceback (most recent call last):
  File "/Users/N133723/Library/Python/3.12/lib/python/site-packages/grpc/_plugin_wrapping.py", line 105, in __call__
    self._metadata_plugin(
  File "/Users/N133723/Library/Python/3.12/lib/python/site-packages/google/auth/transport/grpc.py", line 95, in __call__
    callback(self._get_authorization_headers(context), None)
             ^^^^^^^^^^^^^^^^^^^^^^^^^^^^^^^^^^^^^^^^
  File "/Users/N133723/Library/Python/3.12/lib/python/site-packages/google/auth/transport/grpc.py", line 81, in _get_authorization_headers
    self._credentials.before_request(
  File "/Users/N133723/Library/Python/3.12/lib/python/site-packages/google/auth/credentials.py", line 239, in before_request
    self._blocking_refresh(request)
  File "/Users/N133723/Library/Python/3.12/lib/python/site-packages/google/auth/credentials.py", line 202, in _blocking_refresh
    self.refresh(request)
  File "/Users/N133723/Library/Python/3.12/lib/python/site-packages/google/oauth2/credentials.py", line 409, in refresh
    ) = reauth.refresh_grant(
        ^^^^^^^^^^^^^^^^^^^^^
  File "/Users/N133723/Library/Python/3.12/lib/python/site-packages/google/oauth2/reauth.py", line 349, in refresh_grant
    raise exceptions.RefreshError(
google.auth.exceptions.RefreshError: Reauthentication is needed. Please run `gcloud auth application-default login` to reauthenticate.
ERROR    grpc._plugin_wrapping:_plugin_wrapping.py:109 AuthMetadataPluginCallback "<google.auth.transport.grpc.AuthMetadataPlugin object at 0x108059340>" raised exception!
Traceback (most recent call last):
  File "/Users/N133723/Library/Python/3.12/lib/python/site-packages/grpc/_plugin_wrapping.py", line 105, in __call__
    self._metadata_plugin(
  File "/Users/N133723/Library/Python/3.12/lib/python/site-packages/google/auth/transport/grpc.py", line 95, in __call__
    callback(self._get_authorization_headers(context), None)
             ^^^^^^^^^^^^^^^^^^^^^^^^^^^^^^^^^^^^^^^^
  File "/Users/N133723/Library/Python/3.12/lib/python/site-packages/google/auth/transport/grpc.py", line 81, in _get_authorization_headers
    self._credentials.before_request(
  File "/Users/N133723/Library/Python/3.12/lib/python/site-packages/google/auth/credentials.py", line 239, in before_request
    self._blocking_refresh(request)
  File "/Users/N133723/Library/Python/3.12/lib/python/site-packages/google/auth/credentials.py", line 202, in _blocking_refresh
    self.refresh(request)
  File "/Users/N133723/Library/Python/3.12/lib/python/site-packages/google/oauth2/credentials.py", line 409, in refresh
    ) = reauth.refresh_grant(
        ^^^^^^^^^^^^^^^^^^^^^
  File "/Users/N133723/Library/Python/3.12/lib/python/site-packages/google/oauth2/reauth.py", line 349, in refresh_grant
    raise exceptions.RefreshError(
google.auth.exceptions.RefreshError: Reauthentication is needed. Please run `gcloud auth application-default login` to reauthenticate.
ERROR    grpc._plugin_wrapping:_plugin_wrapping.py:109 AuthMetadataPluginCallback "<google.auth.transport.grpc.AuthMetadataPlugin object at 0x108059340>" raised exception!
Traceback (most recent call last):
  File "/Users/N133723/Library/Python/3.12/lib/python/site-packages/grpc/_plugin_wrapping.py", line 105, in __call__
    self._metadata_plugin(
  File "/Users/N133723/Library/Python/3.12/lib/python/site-packages/google/auth/transport/grpc.py", line 95, in __call__
    callback(self._get_authorization_headers(context), None)
             ^^^^^^^^^^^^^^^^^^^^^^^^^^^^^^^^^^^^^^^^
  File "/Users/N133723/Library/Python/3.12/lib/python/site-packages/google/auth/transport/grpc.py", line 81, in _get_authorization_headers
    self._credentials.before_request(
  File "/Users/N133723/Library/Python/3.12/lib/python/site-packages/google/auth/credentials.py", line 239, in before_request
    self._blocking_refresh(request)
  File "/Users/N133723/Library/Python/3.12/lib/python/site-packages/google/auth/credentials.py", line 202, in _blocking_refresh
    self.refresh(request)
  File "/Users/N133723/Library/Python/3.12/lib/python/site-packages/google/oauth2/credentials.py", line 409, in refresh
    ) = reauth.refresh_grant(
        ^^^^^^^^^^^^^^^^^^^^^
  File "/Users/N133723/Library/Python/3.12/lib/python/site-packages/google/oauth2/reauth.py", line 349, in refresh_grant
    raise exceptions.RefreshError(
google.auth.exceptions.RefreshError: Reauthentication is needed. Please run `gcloud auth application-default login` to reauthenticate.
ERROR    grpc._plugin_wrapping:_plugin_wrapping.py:109 AuthMetadataPluginCallback "<google.auth.transport.grpc.AuthMetadataPlugin object at 0x108059340>" raised exception!
Traceback (most recent call last):
  File "/Users/N133723/Library/Python/3.12/lib/python/site-packages/grpc/_plugin_wrapping.py", line 105, in __call__
    self._metadata_plugin(
  File "/Users/N133723/Library/Python/3.12/lib/python/site-packages/google/auth/transport/grpc.py", line 95, in __call__
    callback(self._get_authorization_headers(context), None)
             ^^^^^^^^^^^^^^^^^^^^^^^^^^^^^^^^^^^^^^^^
  File "/Users/N133723/Library/Python/3.12/lib/python/site-packages/google/auth/transport/grpc.py", line 81, in _get_authorization_headers
    self._credentials.before_request(
  File "/Users/N133723/Library/Python/3.12/lib/python/site-packages/google/auth/credentials.py", line 239, in before_request
    self._blocking_refresh(request)
  File "/Users/N133723/Library/Python/3.12/lib/python/site-packages/google/auth/credentials.py", line 202, in _blocking_refresh
    self.refresh(request)
  File "/Users/N133723/Library/Python/3.12/lib/python/site-packages/google/oauth2/credentials.py", line 409, in refresh
    ) = reauth.refresh_grant(
        ^^^^^^^^^^^^^^^^^^^^^
  File "/Users/N133723/Library/Python/3.12/lib/python/site-packages/google/oauth2/reauth.py", line 349, in refresh_grant
    raise exceptions.RefreshError(
google.auth.exceptions.RefreshError: Reauthentication is needed. Please run `gcloud auth application-default login` to reauthenticate.
ERROR    grpc._plugin_wrapping:_plugin_wrapping.py:109 AuthMetadataPluginCallback "<google.auth.transport.grpc.AuthMetadataPlugin object at 0x108059340>" raised exception!
Traceback (most recent call last):
  File "/Users/N133723/Library/Python/3.12/lib/python/site-packages/grpc/_plugin_wrapping.py", line 105, in __call__
    self._metadata_plugin(
  File "/Users/N133723/Library/Python/3.12/lib/python/site-packages/google/auth/transport/grpc.py", line 95, in __call__
    callback(self._get_authorization_headers(context), None)
             ^^^^^^^^^^^^^^^^^^^^^^^^^^^^^^^^^^^^^^^^
  File "/Users/N133723/Library/Python/3.12/lib/python/site-packages/google/auth/transport/grpc.py", line 81, in _get_authorization_headers
    self._credentials.before_request(
  File "/Users/N133723/Library/Python/3.12/lib/python/site-packages/google/auth/credentials.py", line 239, in before_request
    self._blocking_refresh(request)
  File "/Users/N133723/Library/Python/3.12/lib/python/site-packages/google/auth/credentials.py", line 202, in _blocking_refresh
    self.refresh(request)
  File "/Users/N133723/Library/Python/3.12/lib/python/site-packages/google/oauth2/credentials.py", line 409, in refresh
    ) = reauth.refresh_grant(
        ^^^^^^^^^^^^^^^^^^^^^
  File "/Users/N133723/Library/Python/3.12/lib/python/site-packages/google/oauth2/reauth.py", line 349, in refresh_grant
    raise exceptions.RefreshError(
google.auth.exceptions.RefreshError: Reauthentication is needed. Please run `gcloud auth application-default login` to reauthenticate.
ERROR    grpc._plugin_wrapping:_plugin_wrapping.py:109 AuthMetadataPluginCallback "<google.auth.transport.grpc.AuthMetadataPlugin object at 0x108059340>" raised exception!
Traceback (most recent call last):
  File "/Users/N133723/Library/Python/3.12/lib/python/site-packages/grpc/_plugin_wrapping.py", line 105, in __call__
    self._metadata_plugin(
  File "/Users/N133723/Library/Python/3.12/lib/python/site-packages/google/auth/transport/grpc.py", line 95, in __call__
    callback(self._get_authorization_headers(context), None)
             ^^^^^^^^^^^^^^^^^^^^^^^^^^^^^^^^^^^^^^^^
  File "/Users/N133723/Library/Python/3.12/lib/python/site-packages/google/auth/transport/grpc.py", line 81, in _get_authorization_headers
    self._credentials.before_request(
  File "/Users/N133723/Library/Python/3.12/lib/python/site-packages/google/auth/credentials.py", line 239, in before_request
    self._blocking_refresh(request)
  File "/Users/N133723/Library/Python/3.12/lib/python/site-packages/google/auth/credentials.py", line 202, in _blocking_refresh
    self.refresh(request)
  File "/Users/N133723/Library/Python/3.12/lib/python/site-packages/google/oauth2/credentials.py", line 409, in refresh
    ) = reauth.refresh_grant(
        ^^^^^^^^^^^^^^^^^^^^^
  File "/Users/N133723/Library/Python/3.12/lib/python/site-packages/google/oauth2/reauth.py", line 349, in refresh_grant
    raise exceptions.RefreshError(
google.auth.exceptions.RefreshError: Reauthentication is needed. Please run `gcloud auth application-default login` to reauthenticate.
ERROR    grpc._plugin_wrapping:_plugin_wrapping.py:109 AuthMetadataPluginCallback "<google.auth.transport.grpc.AuthMetadataPlugin object at 0x108059340>" raised exception!
Traceback (most recent call last):
  File "/Users/N133723/Library/Python/3.12/lib/python/site-packages/grpc/_plugin_wrapping.py", line 105, in __call__
    self._metadata_plugin(
  File "/Users/N133723/Library/Python/3.12/lib/python/site-packages/google/auth/transport/grpc.py", line 95, in __call__
    callback(self._get_authorization_headers(context), None)
             ^^^^^^^^^^^^^^^^^^^^^^^^^^^^^^^^^^^^^^^^
  File "/Users/N133723/Library/Python/3.12/lib/python/site-packages/google/auth/transport/grpc.py", line 81, in _get_authorization_headers
    self._credentials.before_request(
  File "/Users/N133723/Library/Python/3.12/lib/python/site-packages/google/auth/credentials.py", line 239, in before_request
    self._blocking_refresh(request)
  File "/Users/N133723/Library/Python/3.12/lib/python/site-packages/google/auth/credentials.py", line 202, in _blocking_refresh
    self.refresh(request)
  File "/Users/N133723/Library/Python/3.12/lib/python/site-packages/google/oauth2/credentials.py", line 409, in refresh
    ) = reauth.refresh_grant(
        ^^^^^^^^^^^^^^^^^^^^^
  File "/Users/N133723/Library/Python/3.12/lib/python/site-packages/google/oauth2/reauth.py", line 349, in refresh_grant
    raise exceptions.RefreshError(
google.auth.exceptions.RefreshError: Reauthentication is needed. Please run `gcloud auth application-default login` to reauthenticate.
ERROR    grpc._plugin_wrapping:_plugin_wrapping.py:109 AuthMetadataPluginCallback "<google.auth.transport.grpc.AuthMetadataPlugin object at 0x108059340>" raised exception!
Traceback (most recent call last):
  File "/Users/N133723/Library/Python/3.12/lib/python/site-packages/grpc/_plugin_wrapping.py", line 105, in __call__
    self._metadata_plugin(
  File "/Users/N133723/Library/Python/3.12/lib/python/site-packages/google/auth/transport/grpc.py", line 95, in __call__
    callback(self._get_authorization_headers(context), None)
             ^^^^^^^^^^^^^^^^^^^^^^^^^^^^^^^^^^^^^^^^
  File "/Users/N133723/Library/Python/3.12/lib/python/site-packages/google/auth/transport/grpc.py", line 81, in _get_authorization_headers
    self._credentials.before_request(
  File "/Users/N133723/Library/Python/3.12/lib/python/site-packages/google/auth/credentials.py", line 239, in before_request
    self._blocking_refresh(request)
  File "/Users/N133723/Library/Python/3.12/lib/python/site-packages/google/auth/credentials.py", line 202, in _blocking_refresh
    self.refresh(request)
  File "/Users/N133723/Library/Python/3.12/lib/python/site-packages/google/oauth2/credentials.py", line 409, in refresh
    ) = reauth.refresh_grant(
        ^^^^^^^^^^^^^^^^^^^^^
  File "/Users/N133723/Library/Python/3.12/lib/python/site-packages/google/oauth2/reauth.py", line 349, in refresh_grant
    raise exceptions.RefreshError(
google.auth.exceptions.RefreshError: Reauthentication is needed. Please run `gcloud auth application-default login` to reauthenticate.
ERROR    grpc._plugin_wrapping:_plugin_wrapping.py:109 AuthMetadataPluginCallback "<google.auth.transport.grpc.AuthMetadataPlugin object at 0x108059340>" raised exception!
Traceback (most recent call last):
  File "/Users/N133723/Library/Python/3.12/lib/python/site-packages/grpc/_plugin_wrapping.py", line 105, in __call__
    self._metadata_plugin(
  File "/Users/N133723/Library/Python/3.12/lib/python/site-packages/google/auth/transport/grpc.py", line 95, in __call__
    callback(self._get_authorization_headers(context), None)
             ^^^^^^^^^^^^^^^^^^^^^^^^^^^^^^^^^^^^^^^^
  File "/Users/N133723/Library/Python/3.12/lib/python/site-packages/google/auth/transport/grpc.py", line 81, in _get_authorization_headers
    self._credentials.before_request(
  File "/Users/N133723/Library/Python/3.12/lib/python/site-packages/google/auth/credentials.py", line 239, in before_request
    self._blocking_refresh(request)
  File "/Users/N133723/Library/Python/3.12/lib/python/site-packages/google/auth/credentials.py", line 202, in _blocking_refresh
    self.refresh(request)
  File "/Users/N133723/Library/Python/3.12/lib/python/site-packages/google/oauth2/credentials.py", line 409, in refresh
    ) = reauth.refresh_grant(
        ^^^^^^^^^^^^^^^^^^^^^
  File "/Users/N133723/Library/Python/3.12/lib/python/site-packages/google/oauth2/reauth.py", line 349, in refresh_grant
    raise exceptions.RefreshError(
google.auth.exceptions.RefreshError: Reauthentication is needed. Please run `gcloud auth application-default login` to reauthenticate.
ERROR    grpc._plugin_wrapping:_plugin_wrapping.py:109 AuthMetadataPluginCallback "<google.auth.transport.grpc.AuthMetadataPlugin object at 0x108059340>" raised exception!
Traceback (most recent call last):
  File "/Users/N133723/Library/Python/3.12/lib/python/site-packages/grpc/_plugin_wrapping.py", line 105, in __call__
    self._metadata_plugin(
  File "/Users/N133723/Library/Python/3.12/lib/python/site-packages/google/auth/transport/grpc.py", line 95, in __call__
    callback(self._get_authorization_headers(context), None)
             ^^^^^^^^^^^^^^^^^^^^^^^^^^^^^^^^^^^^^^^^
  File "/Users/N133723/Library/Python/3.12/lib/python/site-packages/google/auth/transport/grpc.py", line 81, in _get_authorization_headers
    self._credentials.before_request(
  File "/Users/N133723/Library/Python/3.12/lib/python/site-packages/google/auth/credentials.py", line 239, in before_request
    self._blocking_refresh(request)
  File "/Users/N133723/Library/Python/3.12/lib/python/site-packages/google/auth/credentials.py", line 202, in _blocking_refresh
    self.refresh(request)
  File "/Users/N133723/Library/Python/3.12/lib/python/site-packages/google/oauth2/credentials.py", line 409, in refresh
    ) = reauth.refresh_grant(
        ^^^^^^^^^^^^^^^^^^^^^
  File "/Users/N133723/Library/Python/3.12/lib/python/site-packages/google/oauth2/reauth.py", line 349, in refresh_grant
    raise exceptions.RefreshError(
google.auth.exceptions.RefreshError: Reauthentication is needed. Please run `gcloud auth application-default login` to reauthenticate.
ERROR    cost_estimator_calc_service:spanner_client.py:85 Error executing async read-only query: Timeout of 30.0s exceeded, last exception: 503 Getting metadata from plugin failed with error: Reauthentication is needed. Please run `gcloud auth application-default login` to reauthenticate.
ERROR    cost_estimator_calc_service:spanner_client.py:86 Query: SELECT DISTINCT PROVIDER_BUSINESS_GROUP_NBR, PRODUCT_CD, RATING_SYSTEM_CD, EPDB_GEOGRAPHIC_AREA_CD
FROM CET_PROVIDERS
WHERE
    PROVIDER_IDENTIFICATION_NBR = @provideridentificationnumber
    AND NETWORK_ID = @networkid
    AND SERVICE_LOCATION_NBR = @servicelocationnumber
ERROR    cost_estimator_calc_service:spanner_client.py:87 Params: {'servicecd': '99214', 'provideridentificationnumber': '0004000317', 'placeofservice': '11', 'servicetype': 'CPT4', 'networkid': '58921', 'servicelocationnumber': '000761071'}
ERROR    cost_estimator_calc_service:spanner_client.py:88 Exception type: <class 'google.api_core.exceptions.RetryError'>
ERROR    cost_estimator_calc_service:spanner_client.py:89 Exception details: Timeout of 30.0s exceeded, last exception: 503 Getting metadata from plugin failed with error: Reauthentication is needed. Please run `gcloud auth application-default login` to reauthenticate.
INFO     cost_estimator_calc_service:cost_estimator_repository_impl.py:72 Provider info result: []
INFO     cost_estimator_calc_service:cost_estimator_repository_impl.py:233 No provider info results found
====================================================================================== short test summary info =======================================================================================
FAILED tests/test_integration_real.py::test_real_service_integration - pydantic_core._pydantic_core.ValidationError: 4 validation errors for CostEstimatorRequest
FAILED tests/test_integration_real.py::test_real_accumulator_service - pydantic_core._pydantic_core.ValidationError: 4 validation errors for CostEstimatorRequest
FAILED tests/test_integration_real.py::test_real_database_integration - assert ('error' in "assert false\n +  where false = isinstance('na', (<class 'int'>, <class 'float'>))" or 'unavailable' in "assert false\n +  where false = isinstance('na', (<class 'int'>, <cl...
============================================================================== 3 failed, 46 passed in 61.46s (0:01:01) ===============================================================================
N133723@MACL2KVFV33RR cost-estimator-calc-service % 
