Traceback (most recent call last):

  File "/Users/c612413/Documents/GitHub/cost-estimator-calc-service/venv/lib/python3.9/site-packages/uvicorn/protocols/http/h11_impl.py", line 403, in run_asgi

    result = await app(  # type: ignore[func-returns-value]

  File "/Users/c612413/Documents/GitHub/cost-estimator-calc-service/venv/lib/python3.9/site-packages/uvicorn/middleware/proxy_headers.py", line 60, in __call__

    return await self.app(scope, receive, send)

  File "/Users/c612413/Documents/GitHub/cost-estimator-calc-service/venv/lib/python3.9/site-packages/fastapi/applications.py", line 1054, in __call__

    await super().__call__(scope, receive, send)

  File "/Users/c612413/Documents/GitHub/cost-estimator-calc-service/venv/lib/python3.9/site-packages/starlette/applications.py", line 112, in __call__

    await self.middleware_stack(scope, receive, send)

  File "/Users/c612413/Documents/GitHub/cost-estimator-calc-service/venv/lib/python3.9/site-packages/starlette/middleware/errors.py", line 187, in __call__

    raise exc

  File "/Users/c612413/Documents/GitHub/cost-estimator-calc-service/venv/lib/python3.9/site-packages/starlette/middleware/errors.py", line 165, in __call__

    await self.app(scope, receive, _send)

  File "/Users/c612413/Documents/GitHub/cost-estimator-calc-service/venv/lib/python3.9/site-packages/starlette/middleware/exceptions.py", line 62, in __call__

    await wrap_app_handling_exceptions(self.app, conn)(scope, receive, send)

  File "/Users/c612413/Documents/GitHub/cost-estimator-calc-service/venv/lib/python3.9/site-packages/starlette/_exception_handler.py", line 53, in wrapped_app

    raise exc

  File "/Users/c612413/Documents/GitHub/cost-estimator-calc-service/venv/lib/python3.9/site-packages/starlette/_exception_handler.py", line 42, in wrapped_app

    await app(scope, receive, sender)

  File "/Users/c612413/Documents/GitHub/cost-estimator-calc-service/venv/lib/python3.9/site-packages/starlette/routing.py", line 714, in __call__

    await self.middleware_stack(scope, receive, send)

  File "/Users/c612413/Documents/GitHub/cost-estimator-calc-service/venv/lib/python3.9/site-packages/starlette/routing.py", line 734, in app

    await route.handle(scope, receive, send)

  File "/Users/c612413/Documents/GitHub/cost-estimator-calc-service/venv/lib/python3.9/site-packages/starlette/routing.py", line 288, in handle

    await self.app(scope, receive, send)

  File "/Users/c612413/Documents/GitHub/cost-estimator-calc-service/venv/lib/python3.9/site-packages/starlette/routing.py", line 76, in app

    await wrap_app_handling_exceptions(app, request)(scope, receive, send)

  File "/Users/c612413/Documents/GitHub/cost-estimator-calc-service/venv/lib/python3.9/site-packages/starlette/_exception_handler.py", line 53, in wrapped_app

    raise exc

  File "/Users/c612413/Documents/GitHub/cost-estimator-calc-service/venv/lib/python3.9/site-packages/starlette/_exception_handler.py", line 42, in wrapped_app

    await app(scope, receive, sender)

  File "/Users/c612413/Documents/GitHub/cost-estimator-calc-service/venv/lib/python3.9/site-packages/starlette/routing.py", line 73, in app

    response = await f(request)

  File "/Users/c612413/Documents/GitHub/cost-estimator-calc-service/venv/lib/python3.9/site-packages/fastapi/routing.py", line 291, in app

    solved_result = await solve_dependencies(

  File "/Users/c612413/Documents/GitHub/cost-estimator-calc-service/venv/lib/python3.9/site-packages/fastapi/dependencies/utils.py", line 640, in solve_dependencies

    solved = await run_in_threadpool(call, **solved_result.values)

  File "/Users/c612413/Documents/GitHub/cost-estimator-calc-service/venv/lib/python3.9/site-packages/starlette/concurrency.py", line 37, in run_in_threadpool

    return await anyio.to_thread.run_sync(func)

  File "/Users/c612413/Documents/GitHub/cost-estimator-calc-service/venv/lib/python3.9/site-packages/anyio/to_thread.py", line 56, in run_sync

    return await get_async_backend().run_sync_in_worker_thread(

  File "/Users/c612413/Documents/GitHub/cost-estimator-calc-service/venv/lib/python3.9/site-packages/anyio/_backends/_asyncio.py", line 2470, in run_sync_in_worker_thread

    return await future

  File "/Users/c612413/Documents/GitHub/cost-estimator-calc-service/venv/lib/python3.9/site-packages/anyio/_backends/_asyncio.py", line 967, in run

    result = context.run(func, *args)

  File "/Users/c612413/Documents/GitHub/cost-estimator-calc-service/app/services/impl/cost_estimation_service_impl.py", line 20, in __init__

    self.repository = CostEstimatorRepositoryImpl()

  File "/Users/c612413/Documents/GitHub/cost-estimator-calc-service/app/repository/impl/cost_estimator_repository_impl.py", line 14, in __init__

    self.db = SpannerClient(

  File "/Users/c612413/Documents/GitHub/cost-estimator-calc-service/app/database/spanner_client.py", line 27, in __init__

    self._client_pool = asyncio.Queue(maxsize=pool_size)

  File "/Library/Developer/CommandLineTools/Library/Frameworks/Python3.framework/Versions/3.9/lib/python3.9/asyncio/queues.py", line 35, in __init__

    self._loop = events.get_event_loop()

  File "/Library/Developer/CommandLineTools/Library/Frameworks/Python3.framework/Versions/3.9/lib/python3.9/asyncio/events.py", line 642, in get_event_loop

    raise RuntimeError('There is no current event loop in thread %r.'

RuntimeError: There is no current event loop in thread 'AnyIO worker thread'.

 
